Workbook

Sheet ENERO
C2: INSTITUTO MUNICIPAL DE DEPORTE Y RECREACIÓN DE YUMBO
C3: PROCESO: GESTIÓN DEL DEPORTE Y LA RECREACIÓN | H3: CÓDIGO | I3: FO-GDD-057
C4: FORMATO | H4: VERSIÓN | I4: 006
C5: PLANILLA ASISTENCIA | H5: FECHA | I5: 46073
B7: CONTRATISTA
B8: LUGAR DE ENTRENO: | S8: TIPO DE DISCAPACIDAD | W8: ORIENTACIÓN SEXUAL | AD8: ETNIA | AK8: COMUNAS - CORREGIMIENTOS
B9: DÍAS: | S9: OLFATIVA Y TACTO | T9: =COUNTIFS(TablaEnero[TIPO DISCAPACIDAD], S9) | W9: HETEROSEXUAL | Z9: =COUNTIFS(TablaEnero[ORI. SEXUAL], W9) | AD9: AFROCOLOMBIANO | AG9: =COUNTIFS(TablaEnero[[ETNIA ]], AD9) | AK9: 1 | AM9: =COUNTIFS(TablaEnero[[ COMUNA]], AK9) | AO9: 3 | AQ9: =COUNTIFS(TablaEnero[[ COMUNA]], AO9)
B10: HORA: | S10: MENTAL | T10: =COUNTIFS(TablaEnero[TIPO DISCAPACIDAD], S10) | W10: LESBIANA | Z10: =COUNTIFS(TablaEnero[ORI. SEXUAL], W10) | AD10: INDÍGENA | AG10: =COUNTIFS(TablaEnero[[ETNIA ]], AD10) | AK10: 2 | AM10: =COUNTIFS(TablaEnero[[ COMUNA]], AK10) | AO10: 4 | AQ10: =COUNTIFS(TablaEnero[[ COMUNA]], AO10)
S11: MOVILIDAD | T11: =COUNTIFS(TablaEnero[TIPO DISCAPACIDAD], S11) | W11: ASEXUAL | Z11: =COUNTIFS(TablaEnero[ORI. SEXUAL], W11) | AD11: MESTIZO | AG11: =COUNTIFS(TablaEnero[[ETNIA ]], AD11) | AK11: ZONA SUR | AM11: =COUNTIFS(TablaEnero[[ COMUNA]], AK11) | AO11: ZONA NORTE | AQ11: =COUNTIFS(TablaEnero[[ COMUNA]], AO11)
B12: PROGRAMAS | C12: MASIFICACIÓN | S12: MULTIPLE | T12: =COUNTIFS(TablaEnero[TIPO DISCAPACIDAD], S12) | W12: BISEXUAL | Z12: =COUNTIFS(TablaEnero[ORI. SEXUAL], W12) | AD12: MULATO | AG12: =COUNTIFS(TablaEnero[[ETNIA ]], AD12) | AK12: ZONA CENTRO | AM12: =COUNTIFS(TablaEnero[[ COMUNA]], AK12)
C13: EDUCACIÓN FÍSICA/ DTE ESCOLAR | D13: PRIMERA INFANCIA | E13: HEVS | F13: RECREACIÓN | H13: D/TE SOCIAL COMUNITARIO | I13: LECYD-CDA | O13: CANTIDAD POR EDADES (AÑOS) | S13: ORAL | T13: =COUNTIFS(TablaEnero[TIPO DISCAPACIDAD], S13) | W13: GAY | Z13: =COUNTIFS(TablaEnero[ORI. SEXUAL], W13) | AD13: NO SABE NO RESPONDE | AG13: =COUNTIFS(TablaEnero[[ETNIA ]], AD13)
K14: HOMBRE | L14: =COUNTIFS(TablaEnero[SEXO], K14) | O14: 0 A 5 | Q14: =COUNTIFS(TablaEnero[EDAD], "<6") | S14: PSICOSOCIAL | T14: =COUNTIFS(TablaEnero[TIPO DISCAPACIDAD], S14) | W14: INTERSEXUAL | Z14: =COUNTIFS(TablaEnero[ORI. SEXUAL], W14) | AD14: PALENQUERO | AG14: =COUNTIFS(TablaEnero[[ETNIA ]], AD14)
O15: 6 A 10 | Q15: =COUNTIFS(TablaEnero[EDAD], ">5", TablaEnero[EDAD], "<11") | S15: VISUAL | T15: =COUNTIFS(TablaEnero[TIPO DISCAPACIDAD], S15) | W15: NO BINARIO | Z15: =COUNTIFS(TablaEnero[ORI. SEXUAL], W15) | AD15: RAIZAL | AG15: =COUNTIFS(TablaEnero[[ETNIA ]], AD15) | AX15: COVENCIONES DE INASISTENCIA
C16: COMPETENCIA | K16: MUJER | L16: =COUNTIFS(TablaEnero[SEXO], K16) | O16: 11 A 14 | Q16: =COUNTIFS(TablaEnero[EDAD], ">10", TablaEnero[EDAD], "<15") | S16: VOZ Y HABLA | T16: =COUNTIFS(TablaEnero[TIPO DISCAPACIDAD], S16) | W16: PANSEXUAL | Z16: =COUNTIFS(TablaEnero[ORI. SEXUAL], W16) | AD16: ROM GITANO | AG16: =COUNTIFS(TablaEnero[[ETNIA ]], AD16)
C17: CONJUNTO | E17: INDIVIDUAL | H17: ADAPTADO | O17: 15 A 19 | Q17: =COUNTIFS(TablaEnero[EDAD], ">14", TablaEnero[EDAD], "<20") | S17: NO SABE NOMBRARLA | T17: =COUNTIFS(TablaEnero[TIPO DISCAPACIDAD], S17) | W17: QUEER | Z17: =COUNTIFS(TablaEnero[ORI. SEXUAL], W17) | AD17: OTRO | AG17: =COUNTIFS(TablaEnero[[ETNIA ]], AD17) | AX17: ASISTE | BA17: A
O18: 20 A 59 | Q18: =COUNTIFS(TablaEnero[EDAD], ">19", TablaEnero[EDAD], "<60") | S18: N/A | T18: =COUNTIFS(TablaEnero[TIPO DISCAPACIDAD], S18) | W18: TRANSEXUAL | Z18: =COUNTIFS(TablaEnero[ORI. SEXUAL], W18) | AX18: FALTA | BA18: F
K19: VICTIMA DE CONFLICTO ARMADO | O19: MÁS DE 60 | Q19: =COUNTIFS(TablaEnero[EDAD], ">59") | W19: OTRO | Z19: =COUNTIFS(TablaEnero[ORI. SEXUAL], W19) | AX19: EXCUSA | BA19: E
K20: SI | L20: =COUNTIF(TablaEnero[VICTIMA CONF. ARMADO], K20)
K21: NO | L21: =COUNTIF(TablaEnero[VICTIMA CONF. ARMADO], K21) | U21: ENERO | AZ21: TOTAL ASISTENCIA
A23: No | B23: NOMBRE | C23: PRIMER APELLIDO | D23: SEGUNDO APELLIDO | E23: FECHA DE NACIMIENTO | F23: EDAD | G23: TIPO DOCUMENTO | H23: DOCUMENTO | I23: SEXO | J23: I.E - COLEGIO -GRUPO - CLUB | K23: GRADO | L23: TIPO DISCAPACIDAD | M23: ORI. SEXUAL | N23: VICTIMA CONF. ARMADO | O23: ETNIA | P23: DIRECCIÓN | Q23: BARRIO | R23: COMUNA | S23: EPS | T23: TELEFONO | U23: SA1 | V23: DO2 | W23: LU3 | X23: MA4 | Y23: MI5 | Z23: JU6 | AA23: VI7 | AB23: SA8 | AC23: DO9 | AD23: LU10 | AE23: MA11 | AF23: MI12 | AG23: JU13 | AH23: VI14 | AI23: SA15 | AJ23: DO16 | AK23: LU17 | AL23: MA18 | AM23: MI19 | AN23: JU20 | AO23: VI21 | AP23: SA22 | AQ23: DO23 | AR23: LU24 | AS23: MA25 | AT23: MI26 | AU23: JU27 | AV23: VI28 | AW23: SA29 | AX23: DO30 | AY23: LU31 | AZ23: A | BA23: F | BB23: E
F24: =IF(E24="","",DATEDIF(E24,$I$7,"Y")) | R24: =IFERROR(VLOOKUP(TablaEnero[[#This Row],[BARRIO]],SECTOR!$A:$B,2,0),"") | AZ24: =COUNTIF(U24:AY24,"A") | BA24: =COUNTIF(U24:AY24,"F") | BB24: =COUNTIF(U24:AY24,"E")
F25: =IF(E25="","",DATEDIF(E25,$I$7,"Y")) | R25: =IFERROR(VLOOKUP(TablaEnero[[#This Row],[BARRIO]],SECTOR!$A:$B,2,0),"") | AZ25: =COUNTIF(U25:AY25,"A") | BA25: =COUNTIF(U25:AY25,"F") | BB25: =COUNTIF(U25:AY25,"E")
F26: =IF(E26="","",DATEDIF(E26,$I$7,"Y")) | R26: =IFERROR(VLOOKUP(TablaEnero[[#This Row],[BARRIO]],SECTOR!$A:$B,2,0),"") | AZ26: =COUNTIF(U26:AY26,"A") | BA26: =COUNTIF(U26:AY26,"F") | BB26: =COUNTIF(U26:AY26,"E")
F27: =IF(E27="","",DATEDIF(E27,$I$7,"Y")) | R27: =IFERROR(VLOOKUP(TablaEnero[[#This Row],[BARRIO]],SECTOR!$A:$B,2,0),"") | AZ27: =COUNTIF(U27:AY27,"A") | BA27: =COUNTIF(U27:AY27,"F") | BB27: =COUNTIF(U27:AY27,"E")
F28: =IF(E28="","",DATEDIF(E28,$I$7,"Y")) | R28: =IFERROR(VLOOKUP(TablaEnero[[#This Row],[BARRIO]],SECTOR!$A:$B,2,0),"") | AZ28: =COUNTIF(U28:AY28,"A") | BA28: =COUNTIF(U28:AY28,"F") | BB28: =COUNTIF(U28:AY28,"E")
F29: =IF(E29="","",DATEDIF(E29,$I$7,"Y")) | R29: =IFERROR(VLOOKUP(TablaEnero[[#This Row],[BARRIO]],SECTOR!$A:$B,2,0),"") | AZ29: =COUNTIF(U29:AY29,"A") | BA29: =COUNTIF(U29:AY29,"F") | BB29: =COUNTIF(U29:AY29,"E")
F30: =IF(E30="","",DATEDIF(E30,$I$7,"Y")) | R30: =IFERROR(VLOOKUP(TablaEnero[[#This Row],[BARRIO]],SECTOR!$A:$B,2,0),"") | AZ30: =COUNTIF(U30:AY30,"A") | BA30: =COUNTIF(U30:AY30,"F") | BB30: =COUNTIF(U30:AY30,"E")
F31: =IF(E31="","",DATEDIF(E31,$I$7,"Y")) | R31: =IFERROR(VLOOKUP(TablaEnero[[#This Row],[BARRIO]],SECTOR!$A:$B,2,0),"") | AZ31: =COUNTIF(U31:AY31,"A") | BA31: =COUNTIF(U31:AY31,"F") | BB31: =COUNTIF(U31:AY31,"E")
F32: =IF(E32="","",DATEDIF(E32,$I$7,"Y")) | R32: =IFERROR(VLOOKUP(TablaEnero[[#This Row],[BARRIO]],SECTOR!$A:$B,2,0),"") | AZ32: =COUNTIF(U32:AY32,"A") | BA32: =COUNTIF(U32:AY32,"F") | BB32: =COUNTIF(U32:AY32,"E")
F33: =IF(E33="","",DATEDIF(E33,$I$7,"Y")) | R33: =IFERROR(VLOOKUP(TablaEnero[[#This Row],[BARRIO]],SECTOR!$A:$B,2,0),"") | AZ33: =COUNTIF(U33:AY33,"A") | BA33: =COUNTIF(U33:AY33,"F") | BB33: =COUNTIF(U33:AY33,"E")
F34: =IF(E34="","",DATEDIF(E34,$I$7,"Y")) | R34: =IFERROR(VLOOKUP(TablaEnero[[#This Row],[BARRIO]],SECTOR!$A:$B,2,0),"") | AZ34: =COUNTIF(U34:AY34,"A") | BA34: =COUNTIF(U34:AY34,"F") | BB34: =COUNTIF(U34:AY34,"E")
F35: =IF(E35="","",DATEDIF(E35,$I$7,"Y")) | R35: =IFERROR(VLOOKUP(TablaEnero[[#This Row],[BARRIO]],SECTOR!$A:$B,2,0),"") | AZ35: =COUNTIF(U35:AY35,"A") | BA35: =COUNTIF(U35:AY35,"F") | BB35: =COUNTIF(U35:AY35,"E")
... F504: =IF(E504="","",DATEDIF(E504,$I$7,"Y")) | R504: =IFERROR(VLOOKUP(TablaEnero[[#This Row],[BARRIO]],SECTOR!$A:$B,2,0),"") | AZ504: =COUNTIF(U504:AY504,"A") | BA504: =COUNTIF(U504:AY504,"F") | BB504: =COUNTIF(U504:AY504,"E")

Sheet FEBRERO
C2: INSTITUTO MUNICIPAL DE DEPORTE Y RECREACIÓN DE YUMBO
C3: PROCESO: GESTIÓN DEL DEPORTE Y LA RECREACIÓN | H3: CÓDIGO | I3: FO-GDD-057
C4: FORMATO | H4: VERSIÓN | I4: 006
C5: PLANILLA ASISTENCIA | H5: FECHA | I5: 46073
B7: CONTRATISTA
B8: LUGAR DE ENTRENO: | S8: TIPO DE DISCAPACIDAD | W8: ORIENTACIÓN SEXUAL | AD8: ETNIA | AK8: COMUNAS - CORREGIMIENTOS
B9: DÍAS: | S9: OLFATIVA Y TACTO | T9: =COUNTIFS(TablaFebrero[TIPO DISCAPACIDAD], S9) | W9: HETEROSEXUAL | Z9: =COUNTIFS(TablaFebrero[ORI. SEXUAL], W9) | AD9: AFROCOLOMBIANO | AG9: =COUNTIFS(TablaFebrero[[ETNIA ]], AD9) | AK9: 1 | AM9: =COUNTIFS(TablaFebrero[[ COMUNA]], AK9) | AO9: 3 | AQ9: =COUNTIFS(TablaFebrero[[ COMUNA]], AO9)
B10: HORA: | S10: MENTAL | T10: =COUNTIFS(TablaFebrero[TIPO DISCAPACIDAD], S10) | W10: LESBIANA | Z10: =COUNTIFS(TablaFebrero[ORI. SEXUAL], W10) | AD10: INDÍGENA | AG10: =COUNTIFS(TablaFebrero[[ETNIA ]], AD10) | AK10: 2 | AM10: =COUNTIFS(TablaFebrero[[ COMUNA]], AK10) | AO10: 4 | AQ10: =COUNTIFS(TablaFebrero[[ COMUNA]], AO10)
S11: MOVILIDAD | T11: =COUNTIFS(TablaFebrero[TIPO DISCAPACIDAD], S11) | W11: ASEXUAL | Z11: =COUNTIFS(TablaFebrero[ORI. SEXUAL], W11) | AD11: MESTIZO | AG11: =COUNTIFS(TablaFebrero[[ETNIA ]], AD11) | AK11: ZONA SUR | AM11: =COUNTIFS(TablaFebrero[[ COMUNA]], AK11) | AO11: ZONA NORTE | AQ11: =COUNTIFS(TablaFebrero[[ COMUNA]], AO11)
B12: PROGRAMAS | C12: MASIFICACIÓN | S12: MULTIPLE | T12: =COUNTIFS(TablaFebrero[TIPO DISCAPACIDAD], S12) | W12: BISEXUAL | Z12: =COUNTIFS(TablaFebrero[ORI. SEXUAL], W12) | AD12: MULATO | AG12: =COUNTIFS(TablaFebrero[[ETNIA ]], AD12) | AK12: ZONA CENTRO | AM12: =COUNTIFS(TablaFebrero[[ COMUNA]], AK12)
C13: EDUCACIÓN FÍSICA/ DTE ESCOLAR | D13: PRIMERA INFANCIA | E13: HEVS | F13: RECREACIÓN | H13: D/TE SOCIAL COMUNITARIO | I13: LECYD-CDA | O13: CANTIDAD POR EDADES (AÑOS) | S13: ORAL | T13: =COUNTIFS(TablaFebrero[TIPO DISCAPACIDAD], S13) | W13: GAY | Z13: =COUNTIFS(TablaFebrero[ORI. SEXUAL], W13) | AD13: NO SABE NO RESPONDE | AG13: =COUNTIFS(TablaFebrero[[ETNIA ]], AD13)
K14: HOMBRE | L14: =COUNTIFS(TablaFebrero[SEXO], K14) | O14: 0 A 5 | Q14: =COUNTIFS(TablaFebrero[EDAD], "<6") | S14: PSICOSOCIAL | T14: =COUNTIFS(TablaFebrero[TIPO DISCAPACIDAD], S14) | W14: INTERSEXUAL | Z14: =COUNTIFS(TablaFebrero[ORI. SEXUAL], W14) | AD14: PALENQUERO | AG14: =COUNTIFS(TablaFebrero[[ETNIA ]], AD14)
O15: 6 A 10 | Q15: =COUNTIFS(TablaFebrero[EDAD], ">5", TablaFebrero[EDAD], "<11") | S15: VISUAL | T15: =COUNTIFS(TablaFebrero[TIPO DISCAPACIDAD], S15) | W15: NO BINARIO | Z15: =COUNTIFS(TablaFebrero[ORI. SEXUAL], W15) | AD15: RAIZAL | AG15: =COUNTIFS(TablaFebrero[[ETNIA ]], AD15) | AX15: COVENCIONES DE INASISTENCIA
C16: COMPETENCIA | K16: MUJER | L16: =COUNTIFS(TablaFebrero[SEXO], K16) | O16: 11 A 14 | Q16: =COUNTIFS(TablaFebrero[EDAD], ">10", TablaFebrero[EDAD], "<15") | S16: VOZ Y HABLA | T16: =COUNTIFS(TablaFebrero[TIPO DISCAPACIDAD], S16) | W16: PANSEXUAL | Z16: =COUNTIFS(TablaFebrero[ORI. SEXUAL], W16) | AD16: ROM GITANO | AG16: =COUNTIFS(TablaFebrero[[ETNIA ]], AD16)
C17: CONJUNTO | E17: INDIVIDUAL | H17: ADAPTADO | O17: 15 A 19 | Q17: =COUNTIFS(TablaFebrero[EDAD], ">14", TablaFebrero[EDAD], "<20") | S17: NO SABE NOMBRARLA | T17: =COUNTIFS(TablaFebrero[TIPO DISCAPACIDAD], S17) | W17: QUEER | Z17: =COUNTIFS(TablaFebrero[ORI. SEXUAL], W17) | AD17: OTRO | AG17: =COUNTIFS(TablaFebrero[[ETNIA ]], AD17) | AX17: ASISTE | BA17: A
O18: 20 A 59 | Q18: =COUNTIFS(TablaFebrero[EDAD], ">19", TablaFebrero[EDAD], "<60") | S18: N/A | T18: =COUNTIFS(TablaFebrero[TIPO DISCAPACIDAD], S18) | W18: TRANSEXUAL | Z18: =COUNTIFS(TablaFebrero[ORI. SEXUAL], W18) | AX18: FALTA | BA18: F
K19: VICTIMA DE CONFLICTO ARMADO | O19: MÁS DE 60 | Q19: =COUNTIFS(TablaFebrero[EDAD], ">59") | W19: OTRO | Z19: =COUNTIFS(TablaFebrero[ORI. SEXUAL], W19) | AX19: EXCUSA | BA19: E
K20: SI | L20: =COUNTIF(TablaFebrero[VICTIMA CONF. ARMADO], K20)
K21: NO | L21: =COUNTIF(TablaFebrero[VICTIMA CONF. ARMADO], K21) | U21: FEBRERO | AZ21: TOTAL ASISTENCIA
A23: No | B23: NOMBRE | C23: PRIMER APELLIDO | D23: SEGUNDO APELLIDO | E23: FECHA DE NACIMIENTO | F23: EDAD | G23: TIPO DOCUMENTO | H23: DOCUMENTO | I23: SEXO | J23: I.E - COLEGIO -GRUPO - CLUB | K23: GRADO | L23: TIPO DISCAPACIDAD | M23: ORI. SEXUAL | N23: VICTIMA CONF. ARMADO | O23: ETNIA | P23: DIRECCIÓN | Q23: BARRIO | R23: COMUNA | S23: EPS | T23: TELEFONO | U23: SA1 | V23: DO2 | W23: LU3 | X23: MA4 | Y23: MI5 | Z23: JU6 | AA23: VI7 | AB23: SA8 | AC23: DO9 | AD23: LU10 | AE23: MA11 | AF23: MI12 | AG23: JU13 | AH23: VI14 | AI23: SA15 | AJ23: DO16 | AK23: LU17 | AL23: MA18 | AM23: MI19 | AN23: JU20 | AO23: VI21 | AP23: SA22 | AQ23: DO23 | AR23: LU24 | AS23: MA25 | AT23: MI26 | AU23: JU27 | AV23: VI28 | AW23: SA29 | AX23: DO30 | AY23: LU31 | AZ23: A | BA23: F | BB23: E
F24: =IF(E24="","",DATEDIF(E24,$I$7,"Y")) | R24: =IFERROR(VLOOKUP(TablaFebrero[[#This Row],[BARRIO]],SECTOR!$A:$B,2,0),"") | AZ24: =COUNTIF(U24:AY24,"A") | BA24: =COUNTIF(U24:AY24,"F") | BB24: =COUNTIF(U24:AY24,"E")
F25: =IF(E25="","",DATEDIF(E25,$I$7,"Y")) | R25: =IFERROR(VLOOKUP(TablaFebrero[[#This Row],[BARRIO]],SECTOR!$A:$B,2,0),"") | AZ25: =COUNTIF(U25:AY25,"A") | BA25: =COUNTIF(U25:AY25,"F") | BB25: =COUNTIF(U25:AY25,"E")
F26: =IF(E26="","",DATEDIF(E26,$I$7,"Y")) | R26: =IFERROR(VLOOKUP(TablaFebrero[[#This Row],[BARRIO]],SECTOR!$A:$B,2,0),"") | AZ26: =COUNTIF(U26:AY26,"A") | BA26: =COUNTIF(U26:AY26,"F") | BB26: =COUNTIF(U26:AY26,"E")
F27: =IF(E27="","",DATEDIF(E27,$I$7,"Y")) | R27: =IFERROR(VLOOKUP(TablaFebrero[[#This Row],[BARRIO]],SECTOR!$A:$B,2,0),"") | AZ27: =COUNTIF(U27:AY27,"A") | BA27: =COUNTIF(U27:AY27,"F") | BB27: =COUNTIF(U27:AY27,"E")
F28: =IF(E28="","",DATEDIF(E28,$I$7,"Y")) | R28: =IFERROR(VLOOKUP(TablaFebrero[[#This Row],[BARRIO]],SECTOR!$A:$B,2,0),"") | AZ28: =COUNTIF(U28:AY28,"A") | BA28: =COUNTIF(U28:AY28,"F") | BB28: =COUNTIF(U28:AY28,"E")
F29: =IF(E29="","",DATEDIF(E29,$I$7,"Y")) | R29: =IFERROR(VLOOKUP(TablaFebrero[[#This Row],[BARRIO]],SECTOR!$A:$B,2,0),"") | AZ29: =COUNTIF(U29:AY29,"A") | BA29: =COUNTIF(U29:AY29,"F") | BB29: =COUNTIF(U29:AY29,"E")
F30: =IF(E30="","",DATEDIF(E30,$I$7,"Y")) | R30: =IFERROR(VLOOKUP(TablaFebrero[[#This Row],[BARRIO]],SECTOR!$A:$B,2,0),"") | AZ30: =COUNTIF(U30:AY30,"A") | BA30: =COUNTIF(U30:AY30,"F") | BB30: =COUNTIF(U30:AY30,"E")
F31: =IF(E31="","",DATEDIF(E31,$I$7,"Y")) | R31: =IFERROR(VLOOKUP(TablaFebrero[[#This Row],[BARRIO]],SECTOR!$A:$B,2,0),"") | AZ31: =COUNTIF(U31:AY31,"A") | BA31: =COUNTIF(U31:AY31,"F") | BB31: =COUNTIF(U31:AY31,"E")
F32: =IF(E32="","",DATEDIF(E32,$I$7,"Y")) | R32: =IFERROR(VLOOKUP(TablaFebrero[[#This Row],[BARRIO]],SECTOR!$A:$B,2,0),"") | AZ32: =COUNTIF(U32:AY32,"A") | BA32: =COUNTIF(U32:AY32,"F") | BB32: =COUNTIF(U32:AY32,"E")
F33: =IF(E33="","",DATEDIF(E33,$I$7,"Y")) | R33: =IFERROR(VLOOKUP(TablaFebrero[[#This Row],[BARRIO]],SECTOR!$A:$B,2,0),"") | AZ33: =COUNTIF(U33:AY33,"A") | BA33: =COUNTIF(U33:AY33,"F") | BB33: =COUNTIF(U33:AY33,"E")
F34: =IF(E34="","",DATEDIF(E34,$I$7,"Y")) | R34: =IFERROR(VLOOKUP(TablaFebrero[[#This Row],[BARRIO]],SECTOR!$A:$B,2,0),"") | AZ34: =COUNTIF(U34:AY34,"A") | BA34: =COUNTIF(U34:AY34,"F") | BB34: =COUNTIF(U34:AY34,"E")
F35: =IF(E35="","",DATEDIF(E35,$I$7,"Y")) | R35: =IFERROR(VLOOKUP(TablaFebrero[[#This Row],[BARRIO]],SECTOR!$A:$B,2,0),"") | AZ35: =COUNTIF(U35:AY35,"A") | BA35: =COUNTIF(U35:AY35,"F") | BB35: =COUNTIF(U35:AY35,"E")
... F504: =IF(E504="","",DATEDIF(E504,$I$7,"Y")) | R504: =IFERROR(VLOOKUP(TablaFebrero[[#This Row],[BARRIO]],SECTOR!$A:$B,2,0),"") | AZ504: =COUNTIF(U504:AY504,"A") | BA504: =COUNTIF(U504:AY504,"F") | BB504: =COUNTIF(U504:AY504,"E")

Sheet MARZO
C2: INSTITUTO MUNICIPAL DE DEPORTE Y RECREACIÓN DE YUMBO
C3: PROCESO: GESTIÓN DEL DEPORTE Y LA RECREACIÓN | H3: CÓDIGO | I3: FO-GDD-057
C4: FORMATO | H4: VERSIÓN | I4: 006
C5: PLANILLA ASISTENCIA | H5: FECHA | I5: 46073
B7: CONTRATISTA
B8: LUGAR DE ENTRENO: | S8: TIPO DE DISCAPACIDAD | W8: ORIENTACIÓN SEXUAL | AD8: ETNIA | AK8: COMUNAS - CORREGIMIENTOS
B9: DÍAS: | S9: OLFATIVA Y TACTO | T9: =COUNTIFS(TablaMarzo[TIPO DISCAPACIDAD], S9) | W9: HETEROSEXUAL | Z9: =COUNTIFS(TablaMarzo[ORI. SEXUAL], W9) | AD9: AFROCOLOMBIANO | AG9: =COUNTIFS(TablaMarzo[[ETNIA ]], AD9) | AK9: 1 | AM9: =COUNTIFS(TablaMarzo[[ COMUNA]], AK9) | AO9: 3 | AQ9: =COUNTIFS(TablaMarzo[[ COMUNA]], AO9)
B10: HORA: | S10: MENTAL | T10: =COUNTIFS(TablaMarzo[TIPO DISCAPACIDAD], S10) | W10: LESBIANA | Z10: =COUNTIFS(TablaMarzo[ORI. SEXUAL], W10) | AD10: INDÍGENA | AG10: =COUNTIFS(TablaMarzo[[ETNIA ]], AD10) | AK10: 2 | AM10: =COUNTIFS(TablaMarzo[[ COMUNA]], AK10) | AO10: 4 | AQ10: =COUNTIFS(TablaMarzo[[ COMUNA]], AO10)
S11: MOVILIDAD | T11: =COUNTIFS(TablaMarzo[TIPO DISCAPACIDAD], S11) | W11: ASEXUAL | Z11: =COUNTIFS(TablaMarzo[ORI. SEXUAL], W11) | AD11: MESTIZO | AG11: =COUNTIFS(TablaMarzo[[ETNIA ]], AD11) | AK11: ZONA SUR | AM11: =COUNTIFS(TablaMarzo[[ COMUNA]], AK11) | AO11: ZONA NORTE | AQ11: =COUNTIFS(TablaMarzo[[ COMUNA]], AO11)
B12: PROGRAMAS | C12: MASIFICACIÓN | S12: MULTIPLE | T12: =COUNTIFS(TablaMarzo[TIPO DISCAPACIDAD], S12) | W12: BISEXUAL | Z12: =COUNTIFS(TablaMarzo[ORI. SEXUAL], W12) | AD12: MULATO | AG12: =COUNTIFS(TablaMarzo[[ETNIA ]], AD12) | AK12: ZONA CENTRO | AM12: =COUNTIFS(TablaMarzo[[ COMUNA]], AK12)
C13: EDUCACIÓN FÍSICA/ DTE ESCOLAR | D13: PRIMERA INFANCIA | E13: HEVS | F13: RECREACIÓN | H13: D/TE SOCIAL COMUNITARIO | I13: LECYD-CDA | O13: CANTIDAD POR EDADES (AÑOS) | S13: ORAL | T13: =COUNTIFS(TablaMarzo[TIPO DISCAPACIDAD], S13) | W13: GAY | Z13: =COUNTIFS(TablaMarzo[ORI. SEXUAL], W13) | AD13: NO SABE NO RESPONDE | AG13: =COUNTIFS(TablaMarzo[[ETNIA ]], AD13)
K14: HOMBRE | L14: =COUNTIFS(TablaMarzo[SEXO], K14) | O14: 0 A 5 | Q14: =COUNTIFS(TablaMarzo[EDAD], "<6") | S14: PSICOSOCIAL | T14: =COUNTIFS(TablaMarzo[TIPO DISCAPACIDAD], S14) | W14: INTERSEXUAL | Z14: =COUNTIFS(TablaMarzo[ORI. SEXUAL], W14) | AD14: PALENQUERO | AG14: =COUNTIFS(TablaMarzo[[ETNIA ]], AD14)
O15: 6 A 10 | Q15: =COUNTIFS(TablaMarzo[EDAD], ">5", TablaMarzo[EDAD], "<11") | S15: VISUAL | T15: =COUNTIFS(TablaMarzo[TIPO DISCAPACIDAD], S15) | W15: NO BINARIO | Z15: =COUNTIFS(TablaMarzo[ORI. SEXUAL], W15) | AD15: RAIZAL | AG15: =COUNTIFS(TablaMarzo[[ETNIA ]], AD15) | AX15: COVENCIONES DE INASISTENCIA
C16: COMPETENCIA | K16: MUJER | L16: =COUNTIFS(TablaMarzo[SEXO], K16) | O16: 11 A 14 | Q16: =COUNTIFS(TablaMarzo[EDAD], ">10", TablaMarzo[EDAD], "<15") | S16: VOZ Y HABLA | T16: =COUNTIFS(TablaMarzo[TIPO DISCAPACIDAD], S16) | W16: PANSEXUAL | Z16: =COUNTIFS(TablaMarzo[ORI. SEXUAL], W16) | AD16: ROM GITANO | AG16: =COUNTIFS(TablaMarzo[[ETNIA ]], AD16)
C17: CONJUNTO | E17: INDIVIDUAL | H17: ADAPTADO | O17: 15 A 19 | Q17: =COUNTIFS(TablaMarzo[EDAD], ">14", TablaMarzo[EDAD], "<20") | S17: NO SABE NOMBRARLA | T17: =COUNTIFS(TablaMarzo[TIPO DISCAPACIDAD], S17) | W17: QUEER | Z17: =COUNTIFS(TablaMarzo[ORI. SEXUAL], W17) | AD17: OTRO | AG17: =COUNTIFS(TablaMarzo[[ETNIA ]], AD17) | AX17: ASISTE | BA17: A
O18: 20 A 59 | Q18: =COUNTIFS(TablaMarzo[EDAD], ">19", TablaMarzo[EDAD], "<60") | S18: N/A | T18: =COUNTIFS(TablaMarzo[TIPO DISCAPACIDAD], S18) | W18: TRANSEXUAL | Z18: =COUNTIFS(TablaMarzo[ORI. SEXUAL], W18) | AX18: FALTA | BA18: F
K19: VICTIMA DE CONFLICTO ARMADO | O19: MÁS DE 60 | Q19: =COUNTIFS(TablaMarzo[EDAD], ">59") | W19: OTRO | Z19: =COUNTIFS(TablaMarzo[ORI. SEXUAL], W19) | AX19: EXCUSA | BA19: E
K20: SI | L20: =COUNTIF(TablaMarzo[VICTIMA CONF. ARMADO], K20)
K21: NO | L21: =COUNTIF(TablaMarzo[VICTIMA CONF. ARMADO], K21) | U21: MARZO | AZ21: TOTAL ASISTENCIA
A23: No | B23: NOMBRE | C23: PRIMER APELLIDO | D23: SEGUNDO APELLIDO | E23: FECHA DE NACIMIENTO | F23: EDAD | G23: TIPO DOCUMENTO | H23: DOCUMENTO | I23: SEXO | J23: I.E - COLEGIO -GRUPO - CLUB | K23: GRADO | L23: TIPO DISCAPACIDAD | M23: ORI. SEXUAL | N23: VICTIMA CONF. ARMADO | O23: ETNIA | P23: DIRECCIÓN | Q23: BARRIO | R23: COMUNA | S23: EPS | T23: TELEFONO | U23: SA1 | V23: DO2 | W23: LU3 | X23: MA4 | Y23: MI5 | Z23: JU6 | AA23: VI7 | AB23: SA8 | AC23: DO9 | AD23: LU10 | AE23: MA11 | AF23: MI12 | AG23: JU13 | AH23: VI14 | AI23: SA15 | AJ23: DO16 | AK23: LU17 | AL23: MA18 | AM23: MI19 | AN23: JU20 | AO23: VI21 | AP23: SA22 | AQ23: DO23 | AR23: LU24 | AS23: MA25 | AT23: MI26 | AU23: JU27 | AV23: VI28 | AW23: SA29 | AX23: DO30 | AY23: LU31 | AZ23: A | BA23: F | BB23: E
F24: =IF(E24="","",DATEDIF(E24,$I$7,"Y")) | R24: =IFERROR(VLOOKUP(TablaMarzo[[#This Row],[BARRIO]],SECTOR!$A:$B,2,0),"") | AZ24: =COUNTIF(U24:AY24,"A") | BA24: =COUNTIF(U24:AY24,"F") | BB24: =COUNTIF(U24:AY24,"E")
F25: =IF(E25="","",DATEDIF(E25,$I$7,"Y")) | R25: =IFERROR(VLOOKUP(TablaMarzo[[#This Row],[BARRIO]],SECTOR!$A:$B,2,0),"") | AZ25: =COUNTIF(U25:AY25,"A") | BA25: =COUNTIF(U25:AY25,"F") | BB25: =COUNTIF(U25:AY25,"E")
F26: =IF(E26="","",DATEDIF(E26,$I$7,"Y")) | R26: =IFERROR(VLOOKUP(TablaMarzo[[#This Row],[BARRIO]],SECTOR!$A:$B,2,0),"") | AZ26: =COUNTIF(U26:AY26,"A") | BA26: =COUNTIF(U26:AY26,"F") | BB26: =COUNTIF(U26:AY26,"E")
F27: =IF(E27="","",DATEDIF(E27,$I$7,"Y")) | R27: =IFERROR(VLOOKUP(TablaMarzo[[#This Row],[BARRIO]],SECTOR!$A:$B,2,0),"") | AZ27: =COUNTIF(U27:AY27,"A") | BA27: =COUNTIF(U27:AY27,"F") | BB27: =COUNTIF(U27:AY27,"E")
F28: =IF(E28="","",DATEDIF(E28,$I$7,"Y")) | R28: =IFERROR(VLOOKUP(TablaMarzo[[#This Row],[BARRIO]],SECTOR!$A:$B,2,0),"") | AZ28: =COUNTIF(U28:AY28,"A") | BA28: =COUNTIF(U28:AY28,"F") | BB28: =COUNTIF(U28:AY28,"E")
F29: =IF(E29="","",DATEDIF(E29,$I$7,"Y")) | R29: =IFERROR(VLOOKUP(TablaMarzo[[#This Row],[BARRIO]],SECTOR!$A:$B,2,0),"") | AZ29: =COUNTIF(U29:AY29,"A") | BA29: =COUNTIF(U29:AY29,"F") | BB29: =COUNTIF(U29:AY29,"E")
F30: =IF(E30="","",DATEDIF(E30,$I$7,"Y")) | R30: =IFERROR(VLOOKUP(TablaMarzo[[#This Row],[BARRIO]],SECTOR!$A:$B,2,0),"") | AZ30: =COUNTIF(U30:AY30,"A") | BA30: =COUNTIF(U30:AY30,"F") | BB30: =COUNTIF(U30:AY30,"E")
F31: =IF(E31="","",DATEDIF(E31,$I$7,"Y")) | R31: =IFERROR(VLOOKUP(TablaMarzo[[#This Row],[BARRIO]],SECTOR!$A:$B,2,0),"") | AZ31: =COUNTIF(U31:AY31,"A") | BA31: =COUNTIF(U31:AY31,"F") | BB31: =COUNTIF(U31:AY31,"E")
F32: =IF(E32="","",DATEDIF(E32,$I$7,"Y")) | R32: =IFERROR(VLOOKUP(TablaMarzo[[#This Row],[BARRIO]],SECTOR!$A:$B,2,0),"") | AZ32: =COUNTIF(U32:AY32,"A") | BA32: =COUNTIF(U32:AY32,"F") | BB32: =COUNTIF(U32:AY32,"E")
F33: =IF(E33="","",DATEDIF(E33,$I$7,"Y")) | R33: =IFERROR(VLOOKUP(TablaMarzo[[#This Row],[BARRIO]],SECTOR!$A:$B,2,0),"") | AZ33: =COUNTIF(U33:AY33,"A") | BA33: =COUNTIF(U33:AY33,"F") | BB33: =COUNTIF(U33:AY33,"E")
F34: =IF(E34="","",DATEDIF(E34,$I$7,"Y")) | R34: =IFERROR(VLOOKUP(TablaMarzo[[#This Row],[BARRIO]],SECTOR!$A:$B,2,0),"") | AZ34: =COUNTIF(U34:AY34,"A") | BA34: =COUNTIF(U34:AY34,"F") | BB34: =COUNTIF(U34:AY34,"E")
F35: =IF(E35="","",DATEDIF(E35,$I$7,"Y")) | R35: =IFERROR(VLOOKUP(TablaMarzo[[#This Row],[BARRIO]],SECTOR!$A:$B,2,0),"") | AZ35: =COUNTIF(U35:AY35,"A") | BA35: =COUNTIF(U35:AY35,"F") | BB35: =COUNTIF(U35:AY35,"E")
... F504: =IF(E504="","",DATEDIF(E504,$I$7,"Y")) | R504: =IFERROR(VLOOKUP(TablaMarzo[[#This Row],[BARRIO]],SECTOR!$A:$B,2,0),"") | AZ504: =COUNTIF(U504:AY504,"A") | BA504: =COUNTIF(U504:AY504,"F") | BB504: =COUNTIF(U504:AY504,"E")

Sheet ABRIL
C2: INSTITUTO MUNICIPAL DE DEPORTE Y RECREACIÓN DE YUMBO
C3: PROCESO: GESTIÓN DEL DEPORTE Y LA RECREACIÓN | H3: CÓDIGO | I3: FO-GDD-057
C4: FORMATO | H4: VERSIÓN | I4: 006
C5: PLANILLA ASISTENCIA | H5: FECHA | I5: 46073
B7: CONTRATISTA
B8: LUGAR DE ENTRENO: | S8: TIPO DE DISCAPACIDAD | W8: ORIENTACIÓN SEXUAL | AD8: ETNIA | AK8: COMUNAS - CORREGIMIENTOS
B9: DÍAS: | S9: OLFATIVA Y TACTO | T9: =COUNTIFS(TablaAbril[TIPO DISCAPACIDAD], S9) | W9: HETEROSEXUAL | Z9: =COUNTIFS(TablaAbril[ORI. SEXUAL], W9) | AD9: AFROCOLOMBIANO | AG9: =COUNTIFS(TablaAbril[[ETNIA ]], AD9) | AK9: 1 | AM9: =COUNTIFS(TablaAbril[[ COMUNA]], AK9) | AO9: 3 | AQ9: =COUNTIFS(TablaAbril[[ COMUNA]], AO9)
B10: HORA: | S10: MENTAL | T10: =COUNTIFS(TablaAbril[TIPO DISCAPACIDAD], S10) | W10: LESBIANA | Z10: =COUNTIFS(TablaAbril[ORI. SEXUAL], W10) | AD10: INDÍGENA | AG10: =COUNTIFS(TablaAbril[[ETNIA ]], AD10) | AK10: 2 | AM10: =COUNTIFS(TablaAbril[[ COMUNA]], AK10) | AO10: 4 | AQ10: =COUNTIFS(TablaAbril[[ COMUNA]], AO10)
S11: MOVILIDAD | T11: =COUNTIFS(TablaAbril[TIPO DISCAPACIDAD], S11) | W11: ASEXUAL | Z11: =COUNTIFS(TablaAbril[ORI. SEXUAL], W11) | AD11: MESTIZO | AG11: =COUNTIFS(TablaAbril[[ETNIA ]], AD11) | AK11: ZONA SUR | AM11: =COUNTIFS(TablaAbril[[ COMUNA]], AK11) | AO11: ZONA NORTE | AQ11: =COUNTIFS(TablaAbril[[ COMUNA]], AO11)
B12: PROGRAMAS | C12: MASIFICACIÓN | S12: MULTIPLE | T12: =COUNTIFS(TablaAbril[TIPO DISCAPACIDAD], S12) | W12: BISEXUAL | Z12: =COUNTIFS(TablaAbril[ORI. SEXUAL], W12) | AD12: MULATO | AG12: =COUNTIFS(TablaAbril[[ETNIA ]], AD12) | AK12: ZONA CENTRO | AM12: =COUNTIFS(TablaAbril[[ COMUNA]], AK12)
C13: EDUCACIÓN FÍSICA/ DTE ESCOLAR | D13: PRIMERA INFANCIA | E13: HEVS | F13: RECREACIÓN | H13: D/TE SOCIAL COMUNITARIO | I13: LECYD-CDA | O13: CANTIDAD POR EDADES (AÑOS) | S13: ORAL | T13: =COUNTIFS(TablaAbril[TIPO DISCAPACIDAD], S13) | W13: GAY | Z13: =COUNTIFS(TablaAbril[ORI. SEXUAL], W13) | AD13: NO SABE NO RESPONDE | AG13: =COUNTIFS(TablaAbril[[ETNIA ]], AD13)
K14: HOMBRE | L14: =COUNTIFS(TablaAbril[SEXO], K14) | O14: 0 A 5 | Q14: =COUNTIFS(TablaAbril[EDAD], "<6") | S14: PSICOSOCIAL | T14: =COUNTIFS(TablaAbril[TIPO DISCAPACIDAD], S14) | W14: INTERSEXUAL | Z14: =COUNTIFS(TablaAbril[ORI. SEXUAL], W14) | AD14: PALENQUERO | AG14: =COUNTIFS(TablaAbril[[ETNIA ]], AD14)
O15: 6 A 10 | Q15: =COUNTIFS(TablaAbril[EDAD], ">5", TablaAbril[EDAD], "<11") | S15: VISUAL | T15: =COUNTIFS(TablaAbril[TIPO DISCAPACIDAD], S15) | W15: NO BINARIO | Z15: =COUNTIFS(TablaAbril[ORI. SEXUAL], W15) | AD15: RAIZAL | AG15: =COUNTIFS(TablaAbril[[ETNIA ]], AD15) | AX15: COVENCIONES DE INASISTENCIA
C16: COMPETENCIA | K16: MUJER | L16: =COUNTIFS(TablaAbril[SEXO], K16) | O16: 11 A 14 | Q16: =COUNTIFS(TablaAbril[EDAD], ">10", TablaAbril[EDAD], "<15") | S16: VOZ Y HABLA | T16: =COUNTIFS(TablaAbril[TIPO DISCAPACIDAD], S16) | W16: PANSEXUAL | Z16: =COUNTIFS(TablaAbril[ORI. SEXUAL], W16) | AD16: ROM GITANO | AG16: =COUNTIFS(TablaAbril[[ETNIA ]], AD16)
C17: CONJUNTO | E17: INDIVIDUAL | H17: ADAPTADO | O17: 15 A 19 | Q17: =COUNTIFS(TablaAbril[EDAD], ">14", TablaAbril[EDAD], "<20") | S17: NO SABE NOMBRARLA | T17: =COUNTIFS(TablaAbril[TIPO DISCAPACIDAD], S17) | W17: QUEER | Z17: =COUNTIFS(TablaAbril[ORI. SEXUAL], W17) | AD17: OTRO | AG17: =COUNTIFS(TablaAbril[[ETNIA ]], AD17) | AX17: ASISTE | BA17: A
O18: 20 A 59 | Q18: =COUNTIFS(TablaAbril[EDAD], ">19", TablaAbril[EDAD], "<60") | S18: N/A | T18: =COUNTIFS(TablaAbril[TIPO DISCAPACIDAD], S18) | W18: TRANSEXUAL | Z18: =COUNTIFS(TablaAbril[ORI. SEXUAL], W18) | AX18: FALTA | BA18: F
K19: VICTIMA DE CONFLICTO ARMADO | O19: MÁS DE 60 | Q19: =COUNTIFS(TablaAbril[EDAD], ">59") | W19: OTRO | Z19: =COUNTIFS(TablaAbril[ORI. SEXUAL], W19) | AX19: EXCUSA | BA19: E
K20: SI | L20: =COUNTIF(TablaAbril[VICTIMA CONF. ARMADO], K20)
K21: NO | L21: =COUNTIF(TablaAbril[VICTIMA CONF. ARMADO], K21) | U21: ABRIL | AZ21: TOTAL ASISTENCIA
A23: No | B23: NOMBRE | C23: PRIMER APELLIDO | D23: SEGUNDO APELLIDO | E23: FECHA DE NACIMIENTO | F23: EDAD | G23: TIPO DOCUMENTO | H23: DOCUMENTO | I23: SEXO | J23: I.E - COLEGIO -GRUPO - CLUB | K23: GRADO | L23: TIPO DISCAPACIDAD | M23: ORI. SEXUAL | N23: VICTIMA CONF. ARMADO | O23: ETNIA | P23: DIRECCIÓN | Q23: BARRIO | R23: COMUNA | S23: EPS | T23: TELEFONO | U23: SA1 | V23: DO2 | W23: LU3 | X23: MA4 | Y23: MI5 | Z23: JU6 | AA23: VI7 | AB23: SA8 | AC23: DO9 | AD23: LU10 | AE23: MA11 | AF23: MI12 | AG23: JU13 | AH23: VI14 | AI23: SA15 | AJ23: DO16 | AK23: LU17 | AL23: MA18 | AM23: MI19 | AN23: JU20 | AO23: VI21 | AP23: SA22 | AQ23: DO23 | AR23: LU24 | AS23: MA25 | AT23: MI26 | AU23: JU27 | AV23: VI28 | AW23: SA29 | AX23: DO30 | AY23: LU31 | AZ23: A | BA23: F | BB23: E
F24: =IF(E24="","",DATEDIF(E24,$I$7,"Y")) | R24: =IFERROR(VLOOKUP(TablaAbril[[#This Row],[BARRIO]],SECTOR!$A:$B,2,0),"") | AZ24: =COUNTIF(U24:AY24,"A") | BA24: =COUNTIF(U24:AY24,"F") | BB24: =COUNTIF(U24:AY24,"E")
F25: =IF(E25="","",DATEDIF(E25,$I$7,"Y")) | R25: =IFERROR(VLOOKUP(TablaAbril[[#This Row],[BARRIO]],SECTOR!$A:$B,2,0),"") | AZ25: =COUNTIF(U25:AY25,"A") | BA25: =COUNTIF(U25:AY25,"F") | BB25: =COUNTIF(U25:AY25,"E")
F26: =IF(E26="","",DATEDIF(E26,$I$7,"Y")) | R26: =IFERROR(VLOOKUP(TablaAbril[[#This Row],[BARRIO]],SECTOR!$A:$B,2,0),"") | AZ26: =COUNTIF(U26:AY26,"A") | BA26: =COUNTIF(U26:AY26,"F") | BB26: =COUNTIF(U26:AY26,"E")
F27: =IF(E27="","",DATEDIF(E27,$I$7,"Y")) | R27: =IFERROR(VLOOKUP(TablaAbril[[#This Row],[BARRIO]],SECTOR!$A:$B,2,0),"") | AZ27: =COUNTIF(U27:AY27,"A") | BA27: =COUNTIF(U27:AY27,"F") | BB27: =COUNTIF(U27:AY27,"E")
F28: =IF(E28="","",DATEDIF(E28,$I$7,"Y")) | R28: =IFERROR(VLOOKUP(TablaAbril[[#This Row],[BARRIO]],SECTOR!$A:$B,2,0),"") | AZ28: =COUNTIF(U28:AY28,"A") | BA28: =COUNTIF(U28:AY28,"F") | BB28: =COUNTIF(U28:AY28,"E")
F29: =IF(E29="","",DATEDIF(E29,$I$7,"Y")) | R29: =IFERROR(VLOOKUP(TablaAbril[[#This Row],[BARRIO]],SECTOR!$A:$B,2,0),"") | AZ29: =COUNTIF(U29:AY29,"A") | BA29: =COUNTIF(U29:AY29,"F") | BB29: =COUNTIF(U29:AY29,"E")
F30: =IF(E30="","",DATEDIF(E30,$I$7,"Y")) | R30: =IFERROR(VLOOKUP(TablaAbril[[#This Row],[BARRIO]],SECTOR!$A:$B,2,0),"") | AZ30: =COUNTIF(U30:AY30,"A") | BA30: =COUNTIF(U30:AY30,"F") | BB30: =COUNTIF(U30:AY30,"E")
F31: =IF(E31="","",DATEDIF(E31,$I$7,"Y")) | R31: =IFERROR(VLOOKUP(TablaAbril[[#This Row],[BARRIO]],SECTOR!$A:$B,2,0),"") | AZ31: =COUNTIF(U31:AY31,"A") | BA31: =COUNTIF(U31:AY31,"F") | BB31: =COUNTIF(U31:AY31,"E")
F32: =IF(E32="","",DATEDIF(E32,$I$7,"Y")) | R32: =IFERROR(VLOOKUP(TablaAbril[[#This Row],[BARRIO]],SECTOR!$A:$B,2,0),"") | AZ32: =COUNTIF(U32:AY32,"A") | BA32: =COUNTIF(U32:AY32,"F") | BB32: =COUNTIF(U32:AY32,"E")
F33: =IF(E33="","",DATEDIF(E33,$I$7,"Y")) | R33: =IFERROR(VLOOKUP(TablaAbril[[#This Row],[BARRIO]],SECTOR!$A:$B,2,0),"") | AZ33: =COUNTIF(U33:AY33,"A") | BA33: =COUNTIF(U33:AY33,"F") | BB33: =COUNTIF(U33:AY33,"E")
F34: =IF(E34="","",DATEDIF(E34,$I$7,"Y")) | R34: =IFERROR(VLOOKUP(TablaAbril[[#This Row],[BARRIO]],SECTOR!$A:$B,2,0),"") | AZ34: =COUNTIF(U34:AY34,"A") | BA34: =COUNTIF(U34:AY34,"F") | BB34: =COUNTIF(U34:AY34,"E")
F35: =IF(E35="","",DATEDIF(E35,$I$7,"Y")) | R35: =IFERROR(VLOOKUP(TablaAbril[[#This Row],[BARRIO]],SECTOR!$A:$B,2,0),"") | AZ35: =COUNTIF(U35:AY35,"A") | BA35: =COUNTIF(U35:AY35,"F") | BB35: =COUNTIF(U35:AY35,"E")
... F504: =IF(E504="","",DATEDIF(E504,$I$7,"Y")) | R504: =IFERROR(VLOOKUP(TablaAbril[[#This Row],[BARRIO]],SECTOR!$A:$B,2,0),"") | AZ504: =COUNTIF(U504:AY504,"A") | BA504: =COUNTIF(U504:AY504,"F") | BB504: =COUNTIF(U504:AY504,"E")

Sheet MAYO
C2: INSTITUTO MUNICIPAL DE DEPORTE Y RECREACIÓN DE YUMBO
C3: PROCESO: GESTIÓN DEL DEPORTE Y LA RECREACIÓN | H3: CÓDIGO | I3: FO-GDD-057
C4: FORMATO | H4: VERSIÓN | I4: 006
C5: PLANILLA ASISTENCIA | H5: FECHA | I5: 46073
B7: CONTRATISTA
B8: LUGAR DE ENTRENO: | S8: TIPO DE DISCAPACIDAD | W8: ORIENTACIÓN SEXUAL | AD8: ETNIA | AK8: COMUNAS - CORREGIMIENTOS
B9: DÍAS: | S9: OLFATIVA Y TACTO | T9: =COUNTIFS(TablaMayo[TIPO DISCAPACIDAD], S9) | W9: HETEROSEXUAL | Z9: =COUNTIFS(TablaMayo[ORI. SEXUAL], W9) | AD9: AFROCOLOMBIANO | AG9: =COUNTIFS(TablaMayo[[ETNIA ]], AD9) | AK9: 1 | AM9: =COUNTIFS(TablaMayo[[ COMUNA]], AK9) | AO9: 3 | AQ9: =COUNTIFS(TablaMayo[[ COMUNA]], AO9)
B10: HORA: | S10: MENTAL | T10: =COUNTIFS(TablaMayo[TIPO DISCAPACIDAD], S10) | W10: LESBIANA | Z10: =COUNTIFS(TablaMayo[ORI. SEXUAL], W10) | AD10: INDÍGENA | AG10: =COUNTIFS(TablaMayo[[ETNIA ]], AD10) | AK10: 2 | AM10: =COUNTIFS(TablaMayo[[ COMUNA]], AK10) | AO10: 4 | AQ10: =COUNTIFS(TablaMayo[[ COMUNA]], AO10)
S11: MOVILIDAD | T11: =COUNTIFS(TablaMayo[TIPO DISCAPACIDAD], S11) | W11: ASEXUAL | Z11: =COUNTIFS(TablaMayo[ORI. SEXUAL], W11) | AD11: MESTIZO | AG11: =COUNTIFS(TablaMayo[[ETNIA ]], AD11) | AK11: ZONA SUR | AM11: =COUNTIFS(TablaMayo[[ COMUNA]], AK11) | AO11: ZONA NORTE | AQ11: =COUNTIFS(TablaMayo[[ COMUNA]], AO11)
B12: PROGRAMAS | C12: MASIFICACIÓN | S12: MULTIPLE | T12: =COUNTIFS(TablaMayo[TIPO DISCAPACIDAD], S12) | W12: BISEXUAL | Z12: =COUNTIFS(TablaMayo[ORI. SEXUAL], W12) | AD12: MULATO | AG12: =COUNTIFS(TablaMayo[[ETNIA ]], AD12) | AK12: ZONA CENTRO | AM12: =COUNTIFS(TablaMayo[[ COMUNA]], AK12)
C13: EDUCACIÓN FÍSICA/ DTE ESCOLAR | D13: PRIMERA INFANCIA | E13: HEVS | F13: RECREACIÓN | H13: D/TE SOCIAL COMUNITARIO | I13: LECYD-CDA | O13: CANTIDAD POR EDADES (AÑOS) | S13: ORAL | T13: =COUNTIFS(TablaMayo[TIPO DISCAPACIDAD], S13) | W13: GAY | Z13: =COUNTIFS(TablaMayo[ORI. SEXUAL], W13) | AD13: NO SABE NO RESPONDE | AG13: =COUNTIFS(TablaMayo[[ETNIA ]], AD13)
K14: HOMBRE | L14: =COUNTIFS(TablaMayo[SEXO], K14) | O14: 0 A 5 | Q14: =COUNTIFS(TablaMayo[EDAD], "<6") | S14: PSICOSOCIAL | T14: =COUNTIFS(TablaMayo[TIPO DISCAPACIDAD], S14) | W14: INTERSEXUAL | Z14: =COUNTIFS(TablaMayo[ORI. SEXUAL], W14) | AD14: PALENQUERO | AG14: =COUNTIFS(TablaMayo[[ETNIA ]], AD14)
O15: 6 A 10 | Q15: =COUNTIFS(TablaMayo[EDAD], ">5", TablaMayo[EDAD], "<11") | S15: VISUAL | T15: =COUNTIFS(TablaMayo[TIPO DISCAPACIDAD], S15) | W15: NO BINARIO | Z15: =COUNTIFS(TablaMayo[ORI. SEXUAL], W15) | AD15: RAIZAL | AG15: =COUNTIFS(TablaMayo[[ETNIA ]], AD15) | AX15: COVENCIONES DE INASISTENCIA
C16: COMPETENCIA | K16: MUJER | L16: =COUNTIFS(TablaMayo[SEXO], K16) | O16: 11 A 14 | Q16: =COUNTIFS(TablaMayo[EDAD], ">10", TablaMayo[EDAD], "<15") | S16: VOZ Y HABLA | T16: =COUNTIFS(TablaMayo[TIPO DISCAPACIDAD], S16) | W16: PANSEXUAL | Z16: =COUNTIFS(TablaMayo[ORI. SEXUAL], W16) | AD16: ROM GITANO | AG16: =COUNTIFS(TablaMayo[[ETNIA ]], AD16)
C17: CONJUNTO | E17: INDIVIDUAL | H17: ADAPTADO | O17: 15 A 19 | Q17: =COUNTIFS(TablaMayo[EDAD], ">14", TablaMayo[EDAD], "<20") | S17: NO SABE NOMBRARLA | T17: =COUNTIFS(TablaMayo[TIPO DISCAPACIDAD], S17) | W17: QUEER | Z17: =COUNTIFS(TablaMayo[ORI. SEXUAL], W17) | AD17: OTRO | AG17: =COUNTIFS(TablaMayo[[ETNIA ]], AD17) | AX17: ASISTE | BA17: A
O18: 20 A 59 | Q18: =COUNTIFS(TablaMayo[EDAD], ">19", TablaMayo[EDAD], "<60") | S18: N/A | T18: =COUNTIFS(TablaMayo[TIPO DISCAPACIDAD], S18) | W18: TRANSEXUAL | Z18: =COUNTIFS(TablaMayo[ORI. SEXUAL], W18) | AX18: FALTA | BA18: F
K19: VICTIMA DE CONFLICTO ARMADO | O19: MÁS DE 60 | Q19: =COUNTIFS(TablaMayo[EDAD], ">59") | W19: OTRO | Z19: =COUNTIFS(TablaMayo[ORI. SEXUAL], W19) | AX19: EXCUSA | BA19: E
K20: SI | L20: =COUNTIF(TablaMayo[VICTIMA CONF. ARMADO], K20)
K21: NO | L21: =COUNTIF(TablaMayo[VICTIMA CONF. ARMADO], K21) | U21: MAYO | AZ21: TOTAL ASISTENCIA
A23: No | B23: NOMBRE | C23: PRIMER APELLIDO | D23: SEGUNDO APELLIDO | E23: FECHA DE NACIMIENTO | F23: EDAD | G23: TIPO DOCUMENTO | H23: DOCUMENTO | I23: SEXO | J23: I.E - COLEGIO -GRUPO - CLUB | K23: GRADO | L23: TIPO DISCAPACIDAD | M23: ORI. SEXUAL | N23: VICTIMA CONF. ARMADO | O23: ETNIA | P23: DIRECCIÓN | Q23: BARRIO | R23: COMUNA | S23: EPS | T23: TELEFONO | U23: SA1 | V23: DO2 | W23: LU3 | X23: MA4 | Y23: MI5 | Z23: JU6 | AA23: VI7 | AB23: SA8 | AC23: DO9 | AD23: LU10 | AE23: MA11 | AF23: MI12 | AG23: JU13 | AH23: VI14 | AI23: SA15 | AJ23: DO16 | AK23: LU17 | AL23: MA18 | AM23: MI19 | AN23: JU20 | AO23: VI21 | AP23: SA22 | AQ23: DO23 | AR23: LU24 | AS23: MA25 | AT23: MI26 | AU23: JU27 | AV23: VI28 | AW23: SA29 | AX23: DO30 | AY23: LU31 | AZ23: A | BA23: F | BB23: E
F24: =IF(E24="","",DATEDIF(E24,$I$7,"Y")) | R24: =IFERROR(VLOOKUP(TablaMayo[[#This Row],[BARRIO]],SECTOR!$A:$B,2,0),"") | AZ24: =COUNTIF(U24:AY24,"A") | BA24: =COUNTIF(U24:AY24,"F") | BB24: =COUNTIF(U24:AY24,"E")
F25: =IF(E25="","",DATEDIF(E25,$I$7,"Y")) | R25: =IFERROR(VLOOKUP(TablaMayo[[#This Row],[BARRIO]],SECTOR!$A:$B,2,0),"") | AZ25: =COUNTIF(U25:AY25,"A") | BA25: =COUNTIF(U25:AY25,"F") | BB25: =COUNTIF(U25:AY25,"E")
F26: =IF(E26="","",DATEDIF(E26,$I$7,"Y")) | R26: =IFERROR(VLOOKUP(TablaMayo[[#This Row],[BARRIO]],SECTOR!$A:$B,2,0),"") | AZ26: =COUNTIF(U26:AY26,"A") | BA26: =COUNTIF(U26:AY26,"F") | BB26: =COUNTIF(U26:AY26,"E")
F27: =IF(E27="","",DATEDIF(E27,$I$7,"Y")) | R27: =IFERROR(VLOOKUP(TablaMayo[[#This Row],[BARRIO]],SECTOR!$A:$B,2,0),"") | AZ27: =COUNTIF(U27:AY27,"A") | BA27: =COUNTIF(U27:AY27,"F") | BB27: =COUNTIF(U27:AY27,"E")
F28: =IF(E28="","",DATEDIF(E28,$I$7,"Y")) | R28: =IFERROR(VLOOKUP(TablaMayo[[#This Row],[BARRIO]],SECTOR!$A:$B,2,0),"") | AZ28: =COUNTIF(U28:AY28,"A") | BA28: =COUNTIF(U28:AY28,"F") | BB28: =COUNTIF(U28:AY28,"E")
F29: =IF(E29="","",DATEDIF(E29,$I$7,"Y")) | R29: =IFERROR(VLOOKUP(TablaMayo[[#This Row],[BARRIO]],SECTOR!$A:$B,2,0),"") | AZ29: =COUNTIF(U29:AY29,"A") | BA29: =COUNTIF(U29:AY29,"F") | BB29: =COUNTIF(U29:AY29,"E")
F30: =IF(E30="","",DATEDIF(E30,$I$7,"Y")) | R30: =IFERROR(VLOOKUP(TablaMayo[[#This Row],[BARRIO]],SECTOR!$A:$B,2,0),"") | AZ30: =COUNTIF(U30:AY30,"A") | BA30: =COUNTIF(U30:AY30,"F") | BB30: =COUNTIF(U30:AY30,"E")
F31: =IF(E31="","",DATEDIF(E31,$I$7,"Y")) | R31: =IFERROR(VLOOKUP(TablaMayo[[#This Row],[BARRIO]],SECTOR!$A:$B,2,0),"") | AZ31: =COUNTIF(U31:AY31,"A") | BA31: =COUNTIF(U31:AY31,"F") | BB31: =COUNTIF(U31:AY31,"E")
F32: =IF(E32="","",DATEDIF(E32,$I$7,"Y")) | R32: =IFERROR(VLOOKUP(TablaMayo[[#This Row],[BARRIO]],SECTOR!$A:$B,2,0),"") | AZ32: =COUNTIF(U32:AY32,"A") | BA32: =COUNTIF(U32:AY32,"F") | BB32: =COUNTIF(U32:AY32,"E")
F33: =IF(E33="","",DATEDIF(E33,$I$7,"Y")) | R33: =IFERROR(VLOOKUP(TablaMayo[[#This Row],[BARRIO]],SECTOR!$A:$B,2,0),"") | AZ33: =COUNTIF(U33:AY33,"A") | BA33: =COUNTIF(U33:AY33,"F") | BB33: =COUNTIF(U33:AY33,"E")
F34: =IF(E34="","",DATEDIF(E34,$I$7,"Y")) | R34: =IFERROR(VLOOKUP(TablaMayo[[#This Row],[BARRIO]],SECTOR!$A:$B,2,0),"") | AZ34: =COUNTIF(U34:AY34,"A") | BA34: =COUNTIF(U34:AY34,"F") | BB34: =COUNTIF(U34:AY34,"E")
F35: =IF(E35="","",DATEDIF(E35,$I$7,"Y")) | R35: =IFERROR(VLOOKUP(TablaMayo[[#This Row],[BARRIO]],SECTOR!$A:$B,2,0),"") | AZ35: =COUNTIF(U35:AY35,"A") | BA35: =COUNTIF(U35:AY35,"F") | BB35: =COUNTIF(U35:AY35,"E")
... F504: =IF(E504="","",DATEDIF(E504,$I$7,"Y")) | R504: =IFERROR(VLOOKUP(TablaMayo[[#This Row],[BARRIO]],SECTOR!$A:$B,2,0),"") | AZ504: =COUNTIF(U504:AY504,"A") | BA504: =COUNTIF(U504:AY504,"F") | BB504: =COUNTIF(U504:AY504,"E")

Sheet JUNIO
C2: INSTITUTO MUNICIPAL DE DEPORTE Y RECREACIÓN DE YUMBO
C3: PROCESO: GESTIÓN DEL DEPORTE Y LA RECREACIÓN | H3: CÓDIGO | I3: FO-GDD-057
C4: FORMATO | H4: VERSIÓN | I4: 006
C5: PLANILLA ASISTENCIA | H5: FECHA | I5: 46073
B7: CONTRATISTA
B8: LUGAR DE ENTRENO: | S8: TIPO DE DISCAPACIDAD | W8: ORIENTACIÓN SEXUAL | AD8: ETNIA | AK8: COMUNAS - CORREGIMIENTOS
B9: DÍAS: | S9: OLFATIVA Y TACTO | T9: =COUNTIFS(TablaJunio[TIPO DISCAPACIDAD], S9) | W9: HETEROSEXUAL | Z9: =COUNTIFS(TablaJunio[ORI. SEXUAL], W9) | AD9: AFROCOLOMBIANO | AG9: =COUNTIFS(TablaJunio[[ETNIA ]], AD9) | AK9: 1 | AM9: =COUNTIFS(TablaJunio[[ COMUNA]], AK9) | AO9: 3 | AQ9: =COUNTIFS(TablaJunio[[ COMUNA]], AO9)
B10: HORA: | S10: MENTAL | T10: =COUNTIFS(TablaJunio[TIPO DISCAPACIDAD], S10) | W10: LESBIANA | Z10: =COUNTIFS(TablaJunio[ORI. SEXUAL], W10) | AD10: INDÍGENA | AG10: =COUNTIFS(TablaJunio[[ETNIA ]], AD10) | AK10: 2 | AM10: =COUNTIFS(TablaJunio[[ COMUNA]], AK10) | AO10: 4 | AQ10: =COUNTIFS(TablaJunio[[ COMUNA]], AO10)
S11: MOVILIDAD | T11: =COUNTIFS(TablaJunio[TIPO DISCAPACIDAD], S11) | W11: ASEXUAL | Z11: =COUNTIFS(TablaJunio[ORI. SEXUAL], W11) | AD11: MESTIZO | AG11: =COUNTIFS(TablaJunio[[ETNIA ]], AD11) | AK11: ZONA SUR | AM11: =COUNTIFS(TablaJunio[[ COMUNA]], AK11) | AO11: ZONA NORTE | AQ11: =COUNTIFS(TablaJunio[[ COMUNA]], AO11)
B12: PROGRAMAS | C12: MASIFICACIÓN | S12: MULTIPLE | T12: =COUNTIFS(TablaJunio[TIPO DISCAPACIDAD], S12) | W12: BISEXUAL | Z12: =COUNTIFS(TablaJunio[ORI. SEXUAL], W12) | AD12: MULATO | AG12: =COUNTIFS(TablaJunio[[ETNIA ]], AD12) | AK12: ZONA CENTRO | AM12: =COUNTIFS(TablaJunio[[ COMUNA]], AK12)
C13: EDUCACIÓN FÍSICA/ DTE ESCOLAR | D13: PRIMERA INFANCIA | E13: HEVS | F13: RECREACIÓN | H13: D/TE SOCIAL COMUNITARIO | I13: LECYD-CDA | O13: CANTIDAD POR EDADES (AÑOS) | S13: ORAL | T13: =COUNTIFS(TablaJunio[TIPO DISCAPACIDAD], S13) | W13: GAY | Z13: =COUNTIFS(TablaJunio[ORI. SEXUAL], W13) | AD13: NO SABE NO RESPONDE | AG13: =COUNTIFS(TablaJunio[[ETNIA ]], AD13)
K14: HOMBRE | L14: =COUNTIFS(TablaJunio[SEXO], K14) | O14: 0 A 5 | Q14: =COUNTIFS(TablaJunio[EDAD], "<6") | S14: PSICOSOCIAL | T14: =COUNTIFS(TablaJunio[TIPO DISCAPACIDAD], S14) | W14: INTERSEXUAL | Z14: =COUNTIFS(TablaJunio[ORI. SEXUAL], W14) | AD14: PALENQUERO | AG14: =COUNTIFS(TablaJunio[[ETNIA ]], AD14)
O15: 6 A 10 | Q15: =COUNTIFS(TablaJunio[EDAD], ">5", TablaJunio[EDAD], "<11") | S15: VISUAL | T15: =COUNTIFS(TablaJunio[TIPO DISCAPACIDAD], S15) | W15: NO BINARIO | Z15: =COUNTIFS(TablaJunio[ORI. SEXUAL], W15) | AD15: RAIZAL | AG15: =COUNTIFS(TablaJunio[[ETNIA ]], AD15) | AX15: COVENCIONES DE INASISTENCIA
C16: COMPETENCIA | K16: MUJER | L16: =COUNTIFS(TablaJunio[SEXO], K16) | O16: 11 A 14 | Q16: =COUNTIFS(TablaJunio[EDAD], ">10", TablaJunio[EDAD], "<15") | S16: VOZ Y HABLA | T16: =COUNTIFS(TablaJunio[TIPO DISCAPACIDAD], S16) | W16: PANSEXUAL | Z16: =COUNTIFS(TablaJunio[ORI. SEXUAL], W16) | AD16: ROM GITANO | AG16: =COUNTIFS(TablaJunio[[ETNIA ]], AD16)
C17: CONJUNTO | E17: INDIVIDUAL | H17: ADAPTADO | O17: 15 A 19 | Q17: =COUNTIFS(TablaJunio[EDAD], ">14", TablaJunio[EDAD], "<20") | S17: NO SABE NOMBRARLA | T17: =COUNTIFS(TablaJunio[TIPO DISCAPACIDAD], S17) | W17: QUEER | Z17: =COUNTIFS(TablaJunio[ORI. SEXUAL], W17) | AD17: OTRO | AG17: =COUNTIFS(TablaJunio[[ETNIA ]], AD17) | AX17: ASISTE | BA17: A
O18: 20 A 59 | Q18: =COUNTIFS(TablaJunio[EDAD], ">19", TablaJunio[EDAD], "<60") | S18: N/A | T18: =COUNTIFS(TablaJunio[TIPO DISCAPACIDAD], S18) | W18: TRANSEXUAL | Z18: =COUNTIFS(TablaJunio[ORI. SEXUAL], W18) | AX18: FALTA | BA18: F
K19: VICTIMA DE CONFLICTO ARMADO | O19: MÁS DE 60 | Q19: =COUNTIFS(TablaJunio[EDAD], ">59") | W19: OTRO | Z19: =COUNTIFS(TablaJunio[ORI. SEXUAL], W19) | AX19: EXCUSA | BA19: E
K20: SI | L20: =COUNTIF(TablaJunio[VICTIMA CONF. ARMADO], K20)
K21: NO | L21: =COUNTIF(TablaJunio[VICTIMA CONF. ARMADO], K21) | U21: JUNIO | AZ21: TOTAL ASISTENCIA
A23: No | B23: NOMBRE | C23: PRIMER APELLIDO | D23: SEGUNDO APELLIDO | E23: FECHA DE NACIMIENTO | F23: EDAD | G23: TIPO DOCUMENTO | H23: DOCUMENTO | I23: SEXO | J23: I.E - COLEGIO -GRUPO - CLUB | K23: GRADO | L23: TIPO DISCAPACIDAD | M23: ORI. SEXUAL | N23: VICTIMA CONF. ARMADO | O23: ETNIA | P23: DIRECCIÓN | Q23: BARRIO | R23: COMUNA | S23: EPS | T23: TELEFONO | U23: SA1 | V23: DO2 | W23: LU3 | X23: MA4 | Y23: MI5 | Z23: JU6 | AA23: VI7 | AB23: SA8 | AC23: DO9 | AD23: LU10 | AE23: MA11 | AF23: MI12 | AG23: JU13 | AH23: VI14 | AI23: SA15 | AJ23: DO16 | AK23: LU17 | AL23: MA18 | AM23: MI19 | AN23: JU20 | AO23: VI21 | AP23: SA22 | AQ23: DO23 | AR23: LU24 | AS23: MA25 | AT23: MI26 | AU23: JU27 | AV23: VI28 | AW23: SA29 | AX23: DO30 | AY23: LU31 | AZ23: A | BA23: F | BB23: E
F24: =IF(E24="","",DATEDIF(E24,$I$7,"Y")) | R24: =IFERROR(VLOOKUP(TablaJunio[[#This Row],[BARRIO]],SECTOR!$A:$B,2,0),"") | AZ24: =COUNTIF(U24:AY24,"A") | BA24: =COUNTIF(U24:AY24,"F") | BB24: =COUNTIF(U24:AY24,"E")
F25: =IF(E25="","",DATEDIF(E25,$I$7,"Y")) | R25: =IFERROR(VLOOKUP(TablaJunio[[#This Row],[BARRIO]],SECTOR!$A:$B,2,0),"") | AZ25: =COUNTIF(U25:AY25,"A") | BA25: =COUNTIF(U25:AY25,"F") | BB25: =COUNTIF(U25:AY25,"E")
F26: =IF(E26="","",DATEDIF(E26,$I$7,"Y")) | R26: =IFERROR(VLOOKUP(TablaJunio[[#This Row],[BARRIO]],SECTOR!$A:$B,2,0),"") | AZ26: =COUNTIF(U26:AY26,"A") | BA26: =COUNTIF(U26:AY26,"F") | BB26: =COUNTIF(U26:AY26,"E")
F27: =IF(E27="","",DATEDIF(E27,$I$7,"Y")) | R27: =IFERROR(VLOOKUP(TablaJunio[[#This Row],[BARRIO]],SECTOR!$A:$B,2,0),"") | AZ27: =COUNTIF(U27:AY27,"A") | BA27: =COUNTIF(U27:AY27,"F") | BB27: =COUNTIF(U27:AY27,"E")
F28: =IF(E28="","",DATEDIF(E28,$I$7,"Y")) | R28: =IFERROR(VLOOKUP(TablaJunio[[#This Row],[BARRIO]],SECTOR!$A:$B,2,0),"") | AZ28: =COUNTIF(U28:AY28,"A") | BA28: =COUNTIF(U28:AY28,"F") | BB28: =COUNTIF(U28:AY28,"E")
F29: =IF(E29="","",DATEDIF(E29,$I$7,"Y")) | R29: =IFERROR(VLOOKUP(TablaJunio[[#This Row],[BARRIO]],SECTOR!$A:$B,2,0),"") | AZ29: =COUNTIF(U29:AY29,"A") | BA29: =COUNTIF(U29:AY29,"F") | BB29: =COUNTIF(U29:AY29,"E")
F30: =IF(E30="","",DATEDIF(E30,$I$7,"Y")) | R30: =IFERROR(VLOOKUP(TablaJunio[[#This Row],[BARRIO]],SECTOR!$A:$B,2,0),"") | AZ30: =COUNTIF(U30:AY30,"A") | BA30: =COUNTIF(U30:AY30,"F") | BB30: =COUNTIF(U30:AY30,"E")
F31: =IF(E31="","",DATEDIF(E31,$I$7,"Y")) | R31: =IFERROR(VLOOKUP(TablaJunio[[#This Row],[BARRIO]],SECTOR!$A:$B,2,0),"") | AZ31: =COUNTIF(U31:AY31,"A") | BA31: =COUNTIF(U31:AY31,"F") | BB31: =COUNTIF(U31:AY31,"E")
F32: =IF(E32="","",DATEDIF(E32,$I$7,"Y")) | R32: =IFERROR(VLOOKUP(TablaJunio[[#This Row],[BARRIO]],SECTOR!$A:$B,2,0),"") | AZ32: =COUNTIF(U32:AY32,"A") | BA32: =COUNTIF(U32:AY32,"F") | BB32: =COUNTIF(U32:AY32,"E")
F33: =IF(E33="","",DATEDIF(E33,$I$7,"Y")) | R33: =IFERROR(VLOOKUP(TablaJunio[[#This Row],[BARRIO]],SECTOR!$A:$B,2,0),"") | AZ33: =COUNTIF(U33:AY33,"A") | BA33: =COUNTIF(U33:AY33,"F") | BB33: =COUNTIF(U33:AY33,"E")
F34: =IF(E34="","",DATEDIF(E34,$I$7,"Y")) | R34: =IFERROR(VLOOKUP(TablaJunio[[#This Row],[BARRIO]],SECTOR!$A:$B,2,0),"") | AZ34: =COUNTIF(U34:AY34,"A") | BA34: =COUNTIF(U34:AY34,"F") | BB34: =COUNTIF(U34:AY34,"E")
F35: =IF(E35="","",DATEDIF(E35,$I$7,"Y")) | R35: =IFERROR(VLOOKUP(TablaJunio[[#This Row],[BARRIO]],SECTOR!$A:$B,2,0),"") | AZ35: =COUNTIF(U35:AY35,"A") | BA35: =COUNTIF(U35:AY35,"F") | BB35: =COUNTIF(U35:AY35,"E")
... F504: =IF(E504="","",DATEDIF(E504,$I$7,"Y")) | R504: =IFERROR(VLOOKUP(TablaJunio[[#This Row],[BARRIO]],SECTOR!$A:$B,2,0),"") | AZ504: =COUNTIF(U504:AY504,"A") | BA504: =COUNTIF(U504:AY504,"F") | BB504: =COUNTIF(U504:AY504,"E")

Sheet JULIO
C2: INSTITUTO MUNICIPAL DE DEPORTE Y RECREACIÓN DE YUMBO
C3: PROCESO: GESTIÓN DEL DEPORTE Y LA RECREACIÓN | H3: CÓDIGO | I3: FO-GDD-057
C4: FORMATO | H4: VERSIÓN | I4: 006
C5: PLANILLA ASISTENCIA | H5: FECHA | I5: 46073
B7: CONTRATISTA
B8: LUGAR DE ENTRENO: | S8: TIPO DE DISCAPACIDAD | W8: ORIENTACIÓN SEXUAL | AD8: ETNIA | AK8: COMUNAS - CORREGIMIENTOS
B9: DÍAS: | S9: OLFATIVA Y TACTO | T9: =COUNTIFS(TablaJulio[TIPO DISCAPACIDAD], S9) | W9: HETEROSEXUAL | Z9: =COUNTIFS(TablaJulio[ORI. SEXUAL], W9) | AD9: AFROCOLOMBIANO | AG9: =COUNTIFS(TablaJulio[[ETNIA ]], AD9) | AK9: 1 | AM9: =COUNTIFS(TablaJulio[[ COMUNA]], AK9) | AO9: 3 | AQ9: =COUNTIFS(TablaJulio[[ COMUNA]], AO9)
B10: HORA: | S10: MENTAL | T10: =COUNTIFS(TablaJulio[TIPO DISCAPACIDAD], S10) | W10: LESBIANA | Z10: =COUNTIFS(TablaJulio[ORI. SEXUAL], W10) | AD10: INDÍGENA | AG10: =COUNTIFS(TablaJulio[[ETNIA ]], AD10) | AK10: 2 | AM10: =COUNTIFS(TablaJulio[[ COMUNA]], AK10) | AO10: 4 | AQ10: =COUNTIFS(TablaJulio[[ COMUNA]], AO10)
S11: MOVILIDAD | T11: =COUNTIFS(TablaJulio[TIPO DISCAPACIDAD], S11) | W11: ASEXUAL | Z11: =COUNTIFS(TablaJulio[ORI. SEXUAL], W11) | AD11: MESTIZO | AG11: =COUNTIFS(TablaJulio[[ETNIA ]], AD11) | AK11: ZONA SUR | AM11: =COUNTIFS(TablaJulio[[ COMUNA]], AK11) | AO11: ZONA NORTE | AQ11: =COUNTIFS(TablaJulio[[ COMUNA]], AO11)
B12: PROGRAMAS | C12: MASIFICACIÓN | S12: MULTIPLE | T12: =COUNTIFS(TablaJulio[TIPO DISCAPACIDAD], S12) | W12: BISEXUAL | Z12: =COUNTIFS(TablaJulio[ORI. SEXUAL], W12) | AD12: MULATO | AG12: =COUNTIFS(TablaJulio[[ETNIA ]], AD12) | AK12: ZONA CENTRO | AM12: =COUNTIFS(TablaJulio[[ COMUNA]], AK12)
C13: EDUCACIÓN FÍSICA/ DTE ESCOLAR | D13: PRIMERA INFANCIA | E13: HEVS | F13: RECREACIÓN | H13: D/TE SOCIAL COMUNITARIO | I13: LECYD-CDA | O13: CANTIDAD POR EDADES (AÑOS) | S13: ORAL | T13: =COUNTIFS(TablaJulio[TIPO DISCAPACIDAD], S13) | W13: GAY | Z13: =COUNTIFS(TablaJulio[ORI. SEXUAL], W13) | AD13: NO SABE NO RESPONDE | AG13: =COUNTIFS(TablaJulio[[ETNIA ]], AD13)
K14: HOMBRE | L14: =COUNTIFS(TablaJulio[SEXO], K14) | O14: 0 A 5 | Q14: =COUNTIFS(TablaJulio[EDAD], "<6") | S14: PSICOSOCIAL | T14: =COUNTIFS(TablaJulio[TIPO DISCAPACIDAD], S14) | W14: INTERSEXUAL | Z14: =COUNTIFS(TablaJulio[ORI. SEXUAL], W14) | AD14: PALENQUERO | AG14: =COUNTIFS(TablaJulio[[ETNIA ]], AD14)
O15: 6 A 10 | Q15: =COUNTIFS(TablaJulio[EDAD], ">5", TablaJulio[EDAD], "<11") | S15: VISUAL | T15: =COUNTIFS(TablaJulio[TIPO DISCAPACIDAD], S15) | W15: NO BINARIO | Z15: =COUNTIFS(TablaJulio[ORI. SEXUAL], W15) | AD15: RAIZAL | AG15: =COUNTIFS(TablaJulio[[ETNIA ]], AD15) | AX15: COVENCIONES DE INASISTENCIA
C16: COMPETENCIA | K16: MUJER | L16: =COUNTIFS(TablaJulio[SEXO], K16) | O16: 11 A 14 | Q16: =COUNTIFS(TablaJulio[EDAD], ">10", TablaJulio[EDAD], "<15") | S16: VOZ Y HABLA | T16: =COUNTIFS(TablaJulio[TIPO DISCAPACIDAD], S16) | W16: PANSEXUAL | Z16: =COUNTIFS(TablaJulio[ORI. SEXUAL], W16) | AD16: ROM GITANO | AG16: =COUNTIFS(TablaJulio[[ETNIA ]], AD16)
C17: CONJUNTO | E17: INDIVIDUAL | H17: ADAPTADO | O17: 15 A 19 | Q17: =COUNTIFS(TablaJulio[EDAD], ">14", TablaJulio[EDAD], "<20") | S17: NO SABE NOMBRARLA | T17: =COUNTIFS(TablaJulio[TIPO DISCAPACIDAD], S17) | W17: QUEER | Z17: =COUNTIFS(TablaJulio[ORI. SEXUAL], W17) | AD17: OTRO | AG17: =COUNTIFS(TablaJulio[[ETNIA ]], AD17) | AX17: ASISTE | BA17: A
O18: 20 A 59 | Q18: =COUNTIFS(TablaJulio[EDAD], ">19", TablaJulio[EDAD], "<60") | S18: N/A | T18: =COUNTIFS(TablaJulio[TIPO DISCAPACIDAD], S18) | W18: TRANSEXUAL | Z18: =COUNTIFS(TablaJulio[ORI. SEXUAL], W18) | AX18: FALTA | BA18: F
K19: VICTIMA DE CONFLICTO ARMADO | O19: MÁS DE 60 | Q19: =COUNTIFS(TablaJulio[EDAD], ">59") | W19: OTRO | Z19: =COUNTIFS(TablaJulio[ORI. SEXUAL], W19) | AX19: EXCUSA | BA19: E
K20: SI | L20: =COUNTIF(TablaJulio[VICTIMA CONF. ARMADO], K20)
K21: NO | L21: =COUNTIF(TablaJulio[VICTIMA CONF. ARMADO], K21) | U21: JULIO | AZ21: TOTAL ASISTENCIA
A23: No | B23: NOMBRE | C23: PRIMER APELLIDO | D23: SEGUNDO APELLIDO | E23: FECHA DE NACIMIENTO | F23: EDAD | G23: TIPO DOCUMENTO | H23: DOCUMENTO | I23: SEXO | J23: I.E - COLEGIO -GRUPO - CLUB | K23: GRADO | L23: TIPO DISCAPACIDAD | M23: ORI. SEXUAL | N23: VICTIMA CONF. ARMADO | O23: ETNIA | P23: DIRECCIÓN | Q23: BARRIO | R23: COMUNA | S23: EPS | T23: TELEFONO | U23: SA1 | V23: DO2 | W23: LU3 | X23: MA4 | Y23: MI5 | Z23: JU6 | AA23: VI7 | AB23: SA8 | AC23: DO9 | AD23: LU10 | AE23: MA11 | AF23: MI12 | AG23: JU13 | AH23: VI14 | AI23: SA15 | AJ23: DO16 | AK23: LU17 | AL23: MA18 | AM23: MI19 | AN23: JU20 | AO23: VI21 | AP23: SA22 | AQ23: DO23 | AR23: LU24 | AS23: MA25 | AT23: MI26 | AU23: JU27 | AV23: VI28 | AW23: SA29 | AX23: DO30 | AY23: LU31 | AZ23: A | BA23: F | BB23: E
F24: =IF(E24="","",DATEDIF(E24,$I$7,"Y")) | R24: =IFERROR(VLOOKUP(TablaJulio[[#This Row],[BARRIO]],SECTOR!$A:$B,2,0),"") | AZ24: =COUNTIF(U24:AY24,"A") | BA24: =COUNTIF(U24:AY24,"F") | BB24: =COUNTIF(U24:AY24,"E")
F25: =IF(E25="","",DATEDIF(E25,$I$7,"Y")) | R25: =IFERROR(VLOOKUP(TablaJulio[[#This Row],[BARRIO]],SECTOR!$A:$B,2,0),"") | AZ25: =COUNTIF(U25:AY25,"A") | BA25: =COUNTIF(U25:AY25,"F") | BB25: =COUNTIF(U25:AY25,"E")
F26: =IF(E26="","",DATEDIF(E26,$I$7,"Y")) | R26: =IFERROR(VLOOKUP(TablaJulio[[#This Row],[BARRIO]],SECTOR!$A:$B,2,0),"") | AZ26: =COUNTIF(U26:AY26,"A") | BA26: =COUNTIF(U26:AY26,"F") | BB26: =COUNTIF(U26:AY26,"E")
F27: =IF(E27="","",DATEDIF(E27,$I$7,"Y")) | R27: =IFERROR(VLOOKUP(TablaJulio[[#This Row],[BARRIO]],SECTOR!$A:$B,2,0),"") | AZ27: =COUNTIF(U27:AY27,"A") | BA27: =COUNTIF(U27:AY27,"F") | BB27: =COUNTIF(U27:AY27,"E")
F28: =IF(E28="","",DATEDIF(E28,$I$7,"Y")) | R28: =IFERROR(VLOOKUP(TablaJulio[[#This Row],[BARRIO]],SECTOR!$A:$B,2,0),"") | AZ28: =COUNTIF(U28:AY28,"A") | BA28: =COUNTIF(U28:AY28,"F") | BB28: =COUNTIF(U28:AY28,"E")
F29: =IF(E29="","",DATEDIF(E29,$I$7,"Y")) | R29: =IFERROR(VLOOKUP(TablaJulio[[#This Row],[BARRIO]],SECTOR!$A:$B,2,0),"") | AZ29: =COUNTIF(U29:AY29,"A") | BA29: =COUNTIF(U29:AY29,"F") | BB29: =COUNTIF(U29:AY29,"E")
F30: =IF(E30="","",DATEDIF(E30,$I$7,"Y")) | R30: =IFERROR(VLOOKUP(TablaJulio[[#This Row],[BARRIO]],SECTOR!$A:$B,2,0),"") | AZ30: =COUNTIF(U30:AY30,"A") | BA30: =COUNTIF(U30:AY30,"F") | BB30: =COUNTIF(U30:AY30,"E")
F31: =IF(E31="","",DATEDIF(E31,$I$7,"Y")) | R31: =IFERROR(VLOOKUP(TablaJulio[[#This Row],[BARRIO]],SECTOR!$A:$B,2,0),"") | AZ31: =COUNTIF(U31:AY31,"A") | BA31: =COUNTIF(U31:AY31,"F") | BB31: =COUNTIF(U31:AY31,"E")
F32: =IF(E32="","",DATEDIF(E32,$I$7,"Y")) | R32: =IFERROR(VLOOKUP(TablaJulio[[#This Row],[BARRIO]],SECTOR!$A:$B,2,0),"") | AZ32: =COUNTIF(U32:AY32,"A") | BA32: =COUNTIF(U32:AY32,"F") | BB32: =COUNTIF(U32:AY32,"E")
F33: =IF(E33="","",DATEDIF(E33,$I$7,"Y")) | R33: =IFERROR(VLOOKUP(TablaJulio[[#This Row],[BARRIO]],SECTOR!$A:$B,2,0),"") | AZ33: =COUNTIF(U33:AY33,"A") | BA33: =COUNTIF(U33:AY33,"F") | BB33: =COUNTIF(U33:AY33,"E")
F34: =IF(E34="","",DATEDIF(E34,$I$7,"Y")) | R34: =IFERROR(VLOOKUP(TablaJulio[[#This Row],[BARRIO]],SECTOR!$A:$B,2,0),"") | AZ34: =COUNTIF(U34:AY34,"A") | BA34: =COUNTIF(U34:AY34,"F") | BB34: =COUNTIF(U34:AY34,"E")
F35: =IF(E35="","",DATEDIF(E35,$I$7,"Y")) | R35: =IFERROR(VLOOKUP(TablaJulio[[#This Row],[BARRIO]],SECTOR!$A:$B,2,0),"") | AZ35: =COUNTIF(U35:AY35,"A") | BA35: =COUNTIF(U35:AY35,"F") | BB35: =COUNTIF(U35:AY35,"E")
... F504: =IF(E504="","",DATEDIF(E504,$I$7,"Y")) | R504: =IFERROR(VLOOKUP(TablaJulio[[#This Row],[BARRIO]],SECTOR!$A:$B,2,0),"") | AZ504: =COUNTIF(U504:AY504,"A") | BA504: =COUNTIF(U504:AY504,"F") | BB504: =COUNTIF(U504:AY504,"E")

Sheet AGOSTO
C2: INSTITUTO MUNICIPAL DE DEPORTE Y RECREACIÓN DE YUMBO
C3: PROCESO: GESTIÓN DEL DEPORTE Y LA RECREACIÓN | H3: CÓDIGO | I3: FO-GDD-057
C4: FORMATO | H4: VERSIÓN | I4: 006
C5: PLANILLA ASISTENCIA | H5: FECHA | I5: 46073
B7: CONTRATISTA
B8: LUGAR DE ENTRENO: | S8: TIPO DE DISCAPACIDAD | W8: ORIENTACIÓN SEXUAL | AD8: ETNIA | AK8: COMUNAS - CORREGIMIENTOS
B9: DÍAS: | S9: OLFATIVA Y TACTO | T9: =COUNTIFS(TablaAgosto[TIPO DISCAPACIDAD], S9) | W9: HETEROSEXUAL | Z9: =COUNTIFS(TablaAgosto[ORI. SEXUAL], W9) | AD9: AFROCOLOMBIANO | AG9: =COUNTIFS(TablaAgosto[[ETNIA ]], AD9) | AK9: 1 | AM9: =COUNTIFS(TablaAgosto[[ COMUNA]], AK9) | AO9: 3 | AQ9: =COUNTIFS(TablaAgosto[[ COMUNA]], AO9)
B10: HORA: | S10: MENTAL | T10: =COUNTIFS(TablaAgosto[TIPO DISCAPACIDAD], S10) | W10: LESBIANA | Z10: =COUNTIFS(TablaAgosto[ORI. SEXUAL], W10) | AD10: INDÍGENA | AG10: =COUNTIFS(TablaAgosto[[ETNIA ]], AD10) | AK10: 2 | AM10: =COUNTIFS(TablaAgosto[[ COMUNA]], AK10) | AO10: 4 | AQ10: =COUNTIFS(TablaAgosto[[ COMUNA]], AO10)
S11: MOVILIDAD | T11: =COUNTIFS(TablaAgosto[TIPO DISCAPACIDAD], S11) | W11: ASEXUAL | Z11: =COUNTIFS(TablaAgosto[ORI. SEXUAL], W11) | AD11: MESTIZO | AG11: =COUNTIFS(TablaAgosto[[ETNIA ]], AD11) | AK11: ZONA SUR | AM11: =COUNTIFS(TablaAgosto[[ COMUNA]], AK11) | AO11: ZONA NORTE | AQ11: =COUNTIFS(TablaAgosto[[ COMUNA]], AO11)
B12: PROGRAMAS | C12: MASIFICACIÓN | S12: MULTIPLE | T12: =COUNTIFS(TablaAgosto[TIPO DISCAPACIDAD], S12) | W12: BISEXUAL | Z12: =COUNTIFS(TablaAgosto[ORI. SEXUAL], W12) | AD12: MULATO | AG12: =COUNTIFS(TablaAgosto[[ETNIA ]], AD12) | AK12: ZONA CENTRO | AM12: =COUNTIFS(TablaAgosto[[ COMUNA]], AK12)
C13: EDUCACIÓN FÍSICA/ DTE ESCOLAR | D13: PRIMERA INFANCIA | E13: HEVS | F13: RECREACIÓN | H13: D/TE SOCIAL COMUNITARIO | I13: LECYD-CDA | O13: CANTIDAD POR EDADES (AÑOS) | S13: ORAL | T13: =COUNTIFS(TablaAgosto[TIPO DISCAPACIDAD], S13) | W13: GAY | Z13: =COUNTIFS(TablaAgosto[ORI. SEXUAL], W13) | AD13: NO SABE NO RESPONDE | AG13: =COUNTIFS(TablaAgosto[[ETNIA ]], AD13)
K14: HOMBRE | L14: =COUNTIFS(TablaAgosto[SEXO], K14) | O14: 0 A 5 | Q14: =COUNTIFS(TablaAgosto[EDAD], "<6") | S14: PSICOSOCIAL | T14: =COUNTIFS(TablaAgosto[TIPO DISCAPACIDAD], S14) | W14: INTERSEXUAL | Z14: =COUNTIFS(TablaAgosto[ORI. SEXUAL], W14) | AD14: PALENQUERO | AG14: =COUNTIFS(TablaAgosto[[ETNIA ]], AD14)
O15: 6 A 10 | Q15: =COUNTIFS(TablaAgosto[EDAD], ">5", TablaAgosto[EDAD], "<11") | S15: VISUAL | T15: =COUNTIFS(TablaAgosto[TIPO DISCAPACIDAD], S15) | W15: NO BINARIO | Z15: =COUNTIFS(TablaAgosto[ORI. SEXUAL], W15) | AD15: RAIZAL | AG15: =COUNTIFS(TablaAgosto[[ETNIA ]], AD15) | AX15: COVENCIONES DE INASISTENCIA
C16: COMPETENCIA | K16: MUJER | L16: =COUNTIFS(TablaAgosto[SEXO], K16) | O16: 11 A 14 | Q16: =COUNTIFS(TablaAgosto[EDAD], ">10", TablaAgosto[EDAD], "<15") | S16: VOZ Y HABLA | T16: =COUNTIFS(TablaAgosto[TIPO DISCAPACIDAD], S16) | W16: PANSEXUAL | Z16: =COUNTIFS(TablaAgosto[ORI. SEXUAL], W16) | AD16: ROM GITANO | AG16: =COUNTIFS(TablaAgosto[[ETNIA ]], AD16)
C17: CONJUNTO | E17: INDIVIDUAL | H17: ADAPTADO | O17: 15 A 19 | Q17: =COUNTIFS(TablaAgosto[EDAD], ">14", TablaAgosto[EDAD], "<20") | S17: NO SABE NOMBRARLA | T17: =COUNTIFS(TablaAgosto[TIPO DISCAPACIDAD], S17) | W17: QUEER | Z17: =COUNTIFS(TablaAgosto[ORI. SEXUAL], W17) | AD17: OTRO | AG17: =COUNTIFS(TablaAgosto[[ETNIA ]], AD17) | AX17: ASISTE | BA17: A
O18: 20 A 59 | Q18: =COUNTIFS(TablaAgosto[EDAD], ">19", TablaAgosto[EDAD], "<60") | S18: N/A | T18: =COUNTIFS(TablaAgosto[TIPO DISCAPACIDAD], S18) | W18: TRANSEXUAL | Z18: =COUNTIFS(TablaAgosto[ORI. SEXUAL], W18) | AX18: FALTA | BA18: F
K19: VICTIMA DE CONFLICTO ARMADO | O19: MÁS DE 60 | Q19: =COUNTIFS(TablaAgosto[EDAD], ">59") | W19: OTRO | Z19: =COUNTIFS(TablaAgosto[ORI. SEXUAL], W19) | AX19: EXCUSA | BA19: E
K20: SI | L20: =COUNTIF(TablaAgosto[VICTIMA CONF. ARMADO], K20)
K21: NO | L21: =COUNTIF(TablaAgosto[VICTIMA CONF. ARMADO], K21) | U21: AGOSTO | AZ21: TOTAL ASISTENCIA
A23: No | B23: NOMBRE | C23: PRIMER APELLIDO | D23: SEGUNDO APELLIDO | E23: FECHA DE NACIMIENTO | F23: EDAD | G23: TIPO DOCUMENTO | H23: DOCUMENTO | I23: SEXO | J23: I.E - COLEGIO -GRUPO - CLUB | K23: GRADO | L23: TIPO DISCAPACIDAD | M23: ORI. SEXUAL | N23: VICTIMA CONF. ARMADO | O23: ETNIA | P23: DIRECCIÓN | Q23: BARRIO | R23: COMUNA | S23: EPS | T23: TELEFONO | U23: SA1 | V23: DO2 | W23: LU3 | X23: MA4 | Y23: MI5 | Z23: JU6 | AA23: VI7 | AB23: SA8 | AC23: DO9 | AD23: LU10 | AE23: MA11 | AF23: MI12 | AG23: JU13 | AH23: VI14 | AI23: SA15 | AJ23: DO16 | AK23: LU17 | AL23: MA18 | AM23: MI19 | AN23: JU20 | AO23: VI21 | AP23: SA22 | AQ23: DO23 | AR23: LU24 | AS23: MA25 | AT23: MI26 | AU23: JU27 | AV23: VI28 | AW23: SA29 | AX23: DO30 | AY23: LU31 | AZ23: A | BA23: F | BB23: E
F24: =IF(E24="","",DATEDIF(E24,$I$7,"Y")) | R24: =IFERROR(VLOOKUP(TablaAgosto[[#This Row],[BARRIO]],SECTOR!$A:$B,2,0),"") | AZ24: =COUNTIF(U24:AY24,"A") | BA24: =COUNTIF(U24:AY24,"F") | BB24: =COUNTIF(U24:AY24,"E")
F25: =IF(E25="","",DATEDIF(E25,$I$7,"Y")) | R25: =IFERROR(VLOOKUP(TablaAgosto[[#This Row],[BARRIO]],SECTOR!$A:$B,2,0),"") | AZ25: =COUNTIF(U25:AY25,"A") | BA25: =COUNTIF(U25:AY25,"F") | BB25: =COUNTIF(U25:AY25,"E")
F26: =IF(E26="","",DATEDIF(E26,$I$7,"Y")) | R26: =IFERROR(VLOOKUP(TablaAgosto[[#This Row],[BARRIO]],SECTOR!$A:$B,2,0),"") | AZ26: =COUNTIF(U26:AY26,"A") | BA26: =COUNTIF(U26:AY26,"F") | BB26: =COUNTIF(U26:AY26,"E")
F27: =IF(E27="","",DATEDIF(E27,$I$7,"Y")) | R27: =IFERROR(VLOOKUP(TablaAgosto[[#This Row],[BARRIO]],SECTOR!$A:$B,2,0),"") | AZ27: =COUNTIF(U27:AY27,"A") | BA27: =COUNTIF(U27:AY27,"F") | BB27: =COUNTIF(U27:AY27,"E")
F28: =IF(E28="","",DATEDIF(E28,$I$7,"Y")) | R28: =IFERROR(VLOOKUP(TablaAgosto[[#This Row],[BARRIO]],SECTOR!$A:$B,2,0),"") | AZ28: =COUNTIF(U28:AY28,"A") | BA28: =COUNTIF(U28:AY28,"F") | BB28: =COUNTIF(U28:AY28,"E")
F29: =IF(E29="","",DATEDIF(E29,$I$7,"Y")) | R29: =IFERROR(VLOOKUP(TablaAgosto[[#This Row],[BARRIO]],SECTOR!$A:$B,2,0),"") | AZ29: =COUNTIF(U29:AY29,"A") | BA29: =COUNTIF(U29:AY29,"F") | BB29: =COUNTIF(U29:AY29,"E")
F30: =IF(E30="","",DATEDIF(E30,$I$7,"Y")) | R30: =IFERROR(VLOOKUP(TablaAgosto[[#This Row],[BARRIO]],SECTOR!$A:$B,2,0),"") | AZ30: =COUNTIF(U30:AY30,"A") | BA30: =COUNTIF(U30:AY30,"F") | BB30: =COUNTIF(U30:AY30,"E")
F31: =IF(E31="","",DATEDIF(E31,$I$7,"Y")) | R31: =IFERROR(VLOOKUP(TablaAgosto[[#This Row],[BARRIO]],SECTOR!$A:$B,2,0),"") | AZ31: =COUNTIF(U31:AY31,"A") | BA31: =COUNTIF(U31:AY31,"F") | BB31: =COUNTIF(U31:AY31,"E")
F32: =IF(E32="","",DATEDIF(E32,$I$7,"Y")) | R32: =IFERROR(VLOOKUP(TablaAgosto[[#This Row],[BARRIO]],SECTOR!$A:$B,2,0),"") | AZ32: =COUNTIF(U32:AY32,"A") | BA32: =COUNTIF(U32:AY32,"F") | BB32: =COUNTIF(U32:AY32,"E")
F33: =IF(E33="","",DATEDIF(E33,$I$7,"Y")) | R33: =IFERROR(VLOOKUP(TablaAgosto[[#This Row],[BARRIO]],SECTOR!$A:$B,2,0),"") | AZ33: =COUNTIF(U33:AY33,"A") | BA33: =COUNTIF(U33:AY33,"F") | BB33: =COUNTIF(U33:AY33,"E")
F34: =IF(E34="","",DATEDIF(E34,$I$7,"Y")) | R34: =IFERROR(VLOOKUP(TablaAgosto[[#This Row],[BARRIO]],SECTOR!$A:$B,2,0),"") | AZ34: =COUNTIF(U34:AY34,"A") | BA34: =COUNTIF(U34:AY34,"F") | BB34: =COUNTIF(U34:AY34,"E")
F35: =IF(E35="","",DATEDIF(E35,$I$7,"Y")) | R35: =IFERROR(VLOOKUP(TablaAgosto[[#This Row],[BARRIO]],SECTOR!$A:$B,2,0),"") | AZ35: =COUNTIF(U35:AY35,"A") | BA35: =COUNTIF(U35:AY35,"F") | BB35: =COUNTIF(U35:AY35,"E")
... F504: =IF(E504="","",DATEDIF(E504,$I$7,"Y")) | R504: =IFERROR(VLOOKUP(TablaAgosto[[#This Row],[BARRIO]],SECTOR!$A:$B,2,0),"") | AZ504: =COUNTIF(U504:AY504,"A") | BA504: =COUNTIF(U504:AY504,"F") | BB504: =COUNTIF(U504:AY504,"E")

Sheet SEPTIEMBRE
C2: INSTITUTO MUNICIPAL DE DEPORTE Y RECREACIÓN DE YUMBO
